Workbook
Name __xlnm._FilterDatabase: #REF!
Name __xlnm._FilterDatabase_1: #REF!
Name aa: #REF!
Name ddd: #REF!
Name ee: #REF!
Name Goggleplay: #REF!
Name ww: #REF!
Name 내수사양상세기준: #REF!

Sheet Control
B1: ㅌ | C1: TC 추가 NO : | D1: =IFERROR(__xludf.DUMMYFUNCTION("""TC_""&""CT""&""_""&TEXT(ARRAYFORMULA(MAX(IFERROR(VALUE(REGEXEXTRACT(B34:B2095, ""\d+"")))))+1,""0000"")"),"TC_CT_2072")
B2: CCI One App | E2: EU FullTC | L2: 0.166.0 버전 이전 | M2: =IF(COUNTIF(N2:O2,"F")>=1,"FAIL",(IF(COUNTIF(N2:O2,"P")>=1,"PASS",(IF(COUNTIF(N2:O2,"N/T")>=1,"N/T",(IF(COUNTIF(N2:O2,"N/A")>=1,"N/A","-"))))))) | O2: 추가 | P2: 수정 | Q2: 삭제
E3: Project | H3: UID ver. | L3: 0.166.0, 0.167.0, 0.168.0 | M3: =IF(COUNTIF(N3:O3,"F")>=1,"FAIL",(IF(COUNTIF(N3:O3,"P")>=1,"PASS",(IF(COUNTIF(N3:O3,"N/T")>=1,"N/T",(IF(COUNTIF(N3:O3,"N/A")>=1,"N/A","-"))))))) | O3: =COUNTIFS($AB:$AB,"*"&O2&"*") | P3: =COUNTIFS($AB:$AB,"*"&P2&"*") | Q3: =COUNTIFS($AB:$AB,"*"&Q2&"*")
E4: 담당자 | H4: 작성일자 | L4: 0.169.0, 0.170.0, 0.171.0 | M4: =IF(COUNTIF(N4:O4,"F")>=1,"FAIL",(IF(COUNTIF(N4:O4,"P")>=1,"PASS",(IF(COUNTIF(N4:O4,"N/T")>=1,"N/T",(IF(COUNTIF(N4:O4,"N/A")>=1,"N/A","-")))))))
L5: 0.172.0 | M5: =IF(COUNTIF(N5:O5,"F")>=1,"FAIL",(IF(COUNTIF(N5:O5,"P")>=1,"PASS",(IF(COUNTIF(N5:O5,"N/T")>=1,"N/T",(IF(COUNTIF(N5:O5,"N/A")>=1,"N/A","-"))))))) | N5: ← 색깔 업뎃 시 직접 색 지정하지 말고, 이거 복붙해 주세요(누가 처리 했는지 히스토리 보관용)
B6: 테스트 환경
B7: Tester
B9: Test Target | D9: Total TC | E9: RunRate | F9: PassRate | G9: PASS | H9: FAIL | I9: N/A | J9: N/T | N9: Brand | O9: KOA | R9: HOA | U9: GOA
B10: Total | D10: =SUM(D11:D17) | E10: =IFERROR(SUM($G10:J10)/$D10,"-") | F10: =IFERROR($G10/(SUM(G10:H10)),"-") | G10: =SUM(G11:G17) | H10: =SUM(H11:H17) | I10: =SUM(I11:I17) | J10: =SUM(J11:J17) | N10: OS 별 결과 | O10: Total | P10: Android | Q10: iOS | R10: Total | S10: Android | T10: iOS | U10: Total
B11: Control | C11: Common | D11: =COUNTIF($D$21:$D$8853,$C11) | E11: =IFERROR(SUM($G11:J11)/$D11,"-") | F11: =IFERROR($G11/(SUM(G11:H11)),"-") | G11: =COUNTIFS($D:$D,$C11,$N:$N,G$9) | H11: =COUNTIFS($D:$D,$C11,$N:$N,H$9) | I11: =COUNTIFS($D:$D,$C11,$N:$N,I$9) | J11: =COUNTIFS($D:$D,$C11,$N:$N,J$9) | N11: Total | O11: =SUM(O12:O15) | P11: =SUM(P12:P15) | Q11: =SUM(Q12:Q15) | R11: =SUM(R12:R15) | S11: =SUM(S12:S15) | T11: =SUM(T12:T15) | U11: =SUM(U12:U15)
C12: Intro | D12: =COUNTIF($D$21:$D$8853,$C12) | E12: =IFERROR(SUM($G12:J12)/$D12,"-") | F12: =IFERROR($G12/(SUM(G12:H12)),"-") | G12: =COUNTIFS($D:$D,$C12,$N:$N,G$9) | H12: =COUNTIFS($D:$D,$C12,$N:$N,H$9) | I12: =COUNTIFS($D:$D,$C12,$N:$N,I$9) | J12: =COUNTIFS($D:$D,$C12,$N:$N,J$9) | N12: PASS | O12: =COUNTIFS(O$21:O$10779,$N12) | P12: =COUNTIFS(P$21:P$10779,"P") | Q12: =COUNTIFS(Q$21:Q$10779,"P") | R12: =COUNTIFS(R$21:R$10779,$N12) | S12: =COUNTIFS(S$21:S$10779,"P") | T12: =COUNTIFS(T$21:T$10779,"P") | U12: =COUNTIFS(U$21:U$10779,$N12)
C13: 제어 | D13: =COUNTIF($D$21:$D$8853,$C13) | E13: =IFERROR(SUM($G13:J13)/$D13,"-") | F13: =IFERROR($G13/(SUM(G13:H13)),"-") | G13: =COUNTIFS($D:$D,$C13,$N:$N,G$9) | H13: =COUNTIFS($D:$D,$C13,$N:$N,H$9) | I13: =COUNTIFS($D:$D,$C13,$N:$N,I$9) | J13: =COUNTIFS($D:$D,$C13,$N:$N,J$9) | N13: FAIL | O13: =COUNTIFS(O$21:O$10779,$N13) | P13: =COUNTIFS(P$21:P$10779,"F") | Q13: =COUNTIFS(Q$21:Q$10779,"F") | R13: =COUNTIFS(R$21:R$10779,$N13) | S13: =COUNTIFS(S$21:S$10779,"F") | T13: =COUNTIFS(T$21:T$10779,"F") | U13: =COUNTIFS(U$21:U$10779,$N13)
C14: EV | D14: =COUNTIF($D$21:$D$8853,$C14) | E14: =IFERROR(SUM($G14:J14)/$D14,"-") | F14: =IFERROR($G14/(SUM(G14:H14)),"-") | G14: =COUNTIFS($D:$D,$C14,$N:$N,G$9) | H14: =COUNTIFS($D:$D,$C14,$N:$N,H$9) | I14: =COUNTIFS($D:$D,$C14,$N:$N,I$9) | J14: =COUNTIFS($D:$D,$C14,$N:$N,J$9) | N14: N/A | O14: =COUNTIFS(O$21:O$10779,$N14) | P14: =COUNTIFS(P$21:P$10779,$N14) | Q14: =COUNTIFS(Q$21:Q$10779,$N14) | R14: =COUNTIFS(R$21:R$10779,$N14) | S14: =COUNTIFS(S$21:S$10779,$N14) | T14: =COUNTIFS(T$21:T$10779,$N14) | U14: =COUNTIFS(U$21:U$10779,$N14)
C15: 비디오 | D15: =COUNTIF($D$21:$D$8853,$C15) | E15: =IFERROR(SUM($G15:J15)/$D15,"-") | F15: =IFERROR($G15/(SUM(G15:H15)),"-") | G15: =COUNTIFS($D:$D,$C15,$N:$N,G$9) | H15: =COUNTIFS($D:$D,$C15,$N:$N,H$9) | I15: =COUNTIFS($D:$D,$C15,$N:$N,I$9) | J15: =COUNTIFS($D:$D,$C15,$N:$N,J$9) | N15: N/T | O15: =COUNTIFS(O$21:O$10779,$N15) | P15: =COUNTIFS(P$21:P$10779,$N15) | Q15: =COUNTIFS(Q$21:Q$10779,$N15) | R15: =COUNTIFS(R$21:R$10779,$N15) | S15: =COUNTIFS(S$21:S$10779,$N15) | T15: =COUNTIFS(T$21:T$10779,$N15) | U15: =COUNTIFS(U$21:U$10779,$N15)
C16: 능동형 알림 | D16: =COUNTIF($D$21:$D$8853,$C16) | E16: =IFERROR(SUM($G16:J16)/$D16,"-") | F16: =IFERROR($G16/(SUM(G16:H16)),"-") | G16: =COUNTIFS($D:$D,$C16,$N:$N,G$9) | H16: =COUNTIFS($D:$D,$C16,$N:$N,H$9) | I16: =COUNTIFS($D:$D,$C16,$N:$N,I$9) | J16: =COUNTIFS($D:$D,$C16,$N:$N,J$9)
C17: 특화 차종 | D17: =COUNTIF($D$21:$D$8853,$C17) | E17: =IFERROR(SUM($G17:J17)/$D17,"-") | F17: =IFERROR($G17/(SUM(G17:H17)),"-") | G17: =COUNTIFS($D:$D,$C17,$N:$N,G$9) | H17: =COUNTIFS($D:$D,$C17,$N:$N,H$9) | I17: =COUNTIFS($D:$D,$C17,$N:$N,I$9) | J17: =COUNTIFS($D:$D,$C17,$N:$N,J$9)
B19: TC ID | C19: 카테고리 | D19: 대분류 | E19: 중분류 | F19: 소분류 | G19: 향지 | H19: 브랜드 | I19: 우선순위 | J19: Pre-condition | L19: TC procedure | M19: Expected result | N19: Result | O19: KOA Result | P19: KOA | R19: HOA Result | S19: HOA | U19: GOA Result | V19: GOA | X19: Closed 지라 NO | Y19: 지라 NO. | Z19: NT/NA 상세 사유 | AA19: N/A N/T 필터 | AB19: LABEL
J20: App 동작 조건 | K20: 차량 동작 조건 | P20: Android | Q20: iOS | R20: Android Reason | S20: Android | T20: iOS | W20: iOS
B21: TC_CT_0001 | C21: Control | D21: Common | E21: Screen & interaction | F21: 고객 서비스 분기 별 화면 구성 | G21: KR, EU | I21: 4 | J21: 1. CCS 미가입 | L21: 1. Control 진입 | M21: 1. 기본 모드 + 가입 버튼 표출 {CCS_SERVICE_NAME}에 가입하면 더욱 다양한 서비스를 이용하실 수 있어요. 서비스 둘러보기 > {CCS_SERVICE_NAME} 가입 2. 빌트인 캠(기본 기능) 빌트인 캠 (i) 차량에서 빌트인 캠 연결 > 빌트인 캠 저장 영상 > | N21: =IF(COUNTIF(P21:W21,"F")>=1,"FAIL",(IF(COUNTIF(P21:W21,"P")>=1,"PASS",(IF(COUNTIF(P21:W21,"N/T")>=1,"N/T",(IF(COUNTIF(P21:W21,"N/A")>=1,"N/A","-"))))))) | O21: N/T | P21: N/T | T21: P | U21: =IF(COUNTIF(V21:W21,"F")>=1,"FAIL",(IF(COUNTIF(V21:W21,"P")>=1,"PASS",(IF(COUNTIF(V21:W21,"N/T")>=1,"N/T",(IF(COUNTIF(V21:W21,"N/A")>=1,"N/A","-"))))))) | V21: P | W21: P | X21: SPAQA-8491 SPAQA-10188 SPAQA-12476 SPAQA-15943 SPAQA-15677 SPAQA-15632 SPAQA-16255 SPAQA-16256 SPAQA-16861 SPAQA-15905 SPAQA-17072 SPAQA-17083 SPAQA-17666 SPAQA-18975 SPAQA-21550 SPAQA-22842 SPAQA-17666 SPAQA-22999 SPAQA-23000 SPAQA-23001 SPAQA-23433 SPAQA-25008 SPAQA-25803 SPAQA-25804 SPAQA-26284 SPAQA-26282
B22: TC_CT_1559 | C22: Control | D22: Common | E22: Screen & interaction | F22: 고객 서비스 분기 별 화면 구성 | I22: 4 | J22: 1. CCS 미가입 2. 피공유자 계정 | L22: 1. 하단 GNB 영역 확인 | M22: 1. Control 탭 미노출 | N22: =IF(COUNTIF(P22:W22,"F")>=1,"FAIL",(IF(COUNTIF(P22:W22,"P")>=1,"PASS",(IF(COUNTIF(P22:W22,"N/T")>=1,"N/T",(IF(COUNTIF(P22:W22,"N/A")>=1,"N/A","-"))))))) | O22: N/T | P22: N/T | T22: P | U22: =IF(COUNTIF(V22:W22,"F")>=1,"FAIL",(IF(COUNTIF(V22:W22,"P")>=1,"PASS",(IF(COUNTIF(V22:W22,"N/T")>=1,"N/T",(IF(COUNTIF(V22:W22,"N/A")>=1,"N/A","-"))))))) | V22: P | W22: P
B23: TC_CT_1560 | C23: Control | D23: Common | E23: Screen & interaction | F23: 고객 서비스 분기 별 화면 구성 | I23: 5 | J23: 1. 차량 미점유 | L23: 1. Control 진입 | M23: 1. 미점유, 차량 미보유 화면 표출 - CCS 소개, 차량 등록 가이드 문구 표출 {CCS_SERVICE_NAME}에 가입하면 더욱 다양한 서비스를 이용하실 수 있어요. 서비스 둘러보기 > 아이콘 "차량을 등록해 주세요." "빌트인 캠, 차량 제어 서비스를 이용할 수 있습니다." | N23: =IF(COUNTIF(P23:W23,"F")>=1,"FAIL",(IF(COUNTIF(P23:W23,"P")>=1,"PASS",(IF(COUNTIF(P23:W23,"N/T")>=1,"N/T",(IF(COUNTIF(P23:W23,"N/A")>=1,"N/A","-"))))))) | O23: N/T | P23: N/T | T23: N/T | U23: =IF(COUNTIF(V23:W23,"F")>=1,"FAIL",(IF(COUNTIF(V23:W23,"P")>=1,"PASS",(IF(COUNTIF(V23:W23,"N/T")>=1,"N/T",(IF(COUNTIF(V23:W23,"N/A")>=1,"N/A","-"))))))) | V23: N/T | W23: N/T | Z23: 미점유: 신규 계정 생성 후, 차량 한 번도 등록하지 않은 상태의 계정 K : geunhee@poliot.co.kr | AA23: N/T : 특수상황/실패 조건 필요(조건)
B24: TC_CT_1561 | C24: Control | D24: Common | E24: Screen & interaction | F24: 고객 서비스 분기 별 화면 구성 | I24: 5 | J24: 1. CCS 미지원 | L24: 1. Control 진입 | M24: 1. 기본 모드 표출 {CCS_SERVICE_NAME}에 가입하면 더욱 다양한 서비스를 이용하실 수 있어요. 서비스 둘러보기 > 2. 빌트인 캠(기본 기능) 빌트인 캠 (i) 차량에서 빌트인 캠 연결 > 빌트인 캠 저장 영상 > | N24: =IF(COUNTIF(P24:W24,"F")>=1,"FAIL",(IF(COUNTIF(P24:W24,"P")>=1,"PASS",(IF(COUNTIF(P24:W24,"N/T")>=1,"N/T",(IF(COUNTIF(P24:W24,"N/A")>=1,"N/A","-"))))))) | O24: N/T | P24: N/T | T24: N/T | U24: =IF(COUNTIF(V24:W24,"F")>=1,"FAIL",(IF(COUNTIF(V24:W24,"P")>=1,"PASS",(IF(COUNTIF(V24:W24,"N/T")>=1,"N/T",(IF(COUNTIF(V24:W24,"N/A")>=1,"N/A","-"))))))) | V24: N/T | W24: N/T | Z24: H/G : CCS 가입이 불가능한 차량 필요(N/T) K : koa.eu07.gmail.com STONIC | AA24: N/T : 차량/디바이스 필요(조건)
B25: TC_CT_0002 | C25: Control | D25: Common | E25: Screen & interaction | F25: 고객 서비스 분기 별 화면 구성 | G25: KR, EU | I25: 1 | J25: 1. 미로그인 | L25: 1. Control 진입 | M25: 1. 미로그인 모드 표출 2. CCS 소개(닷컴 국가별 URL 적용 필요) +로그인 버튼 title iC IC "{CCS_SERVICE_NAME}에 가입하시면 더 다양한 서비스를 이용하실 수 있어요." 서비스 둘러보기 > "기아차 오너라면 로그인해서 이용해보세요" 로그인 | N25: =IF(COUNTIF(P25:W25,"F")>=1,"FAIL",(IF(COUNTIF(P25:W25,"P")>=1,"PASS",(IF(COUNTIF(P25:W25,"N/T")>=1,"N/T",(IF(COUNTIF(P25:W25,"N/A")>=1,"N/A","-"))))))) | O25: N/T | P25: N/T | T25: P | U25: =IF(COUNTIF(V25:W25,"F")>=1,"FAIL",(IF(COUNTIF(V25:W25,"P")>=1,"PASS",(IF(COUNTIF(V25:W25,"N/T")>=1,"N/T",(IF(COUNTIF(V25:W25,"N/A")>=1,"N/A","-"))))))) | V25: N/A | W25: N/A | X25: SPAQA-8491 SPAQA-10188 SPAQA-12476 SPAQA-13511 SPAQA-14601 SPAQA-15008 SPAQA-22836 SPAQA-25497 SPAQA-25930 | Z25: G : 미로그인 상태로 Control 진입 불가(N/A) | AB25: CheckList
B26: TC_CT_0003 | C26: Control | D26: Common | E26: Screen & interaction | F26: 고객 서비스 분기 별 화면 구성 | G26: KR, EU | I26: 5 | J26: 1. 차량 미보유 | L26: 1. Control 진입 | M26: 1. 미점유, 차량 미보유 화면 2. CCS 소개(닷컴 국가별 URL 적용 필요) +차량 등록 가이드 문구 Title iC IC "{CCS_SERVICE_NAME}에 가입하시면 더 다양한 서비스를 이용하실 수 있어요." 서비스 둘러보기 > 아이콘 "차량을 등록해 주세요." "Dash Cam 차량 제어 서비스를 이용할 수 있습니다." | N26: =IF(COUNTIF(P26:W26,"F")>=1,"FAIL",(IF(COUNTIF(P26:W26,"P")>=1,"PASS",(IF(COUNTIF(P26:W26,"N/T")>=1,"N/T",(IF(COUNTIF(P26:W26,"N/A")>=1,"N/A","-"))))))) | O26: N/T | P26: N/T | T26: P | U26: =IF(COUNTIF(V26:W26,"F")>=1,"FAIL",(IF(COUNTIF(V26:W26,"P")>=1,"PASS",(IF(COUNTIF(V26:W26,"N/T")>=1,"N/T",(IF(COUNTIF(V26:W26,"N/A")>=1,"N/A","-"))))))) | V26: P | W26: P | X26: SPAQA-8491 SPAQA-10188 SPAQA-12476 (ICT) SPAQA-16405 SPAQA-21548 SPAQA-25220 SPAQA-25685 | Z26: 미보유: 차량 등록 후, 삭제한 상태의 계정 K: wbkong@poliot.co.kr H : juwon29@poliot.co.kr G : hmcqa.ccs01@gmail.com | AB26: 실차
B27: TC_CT_0004 | C27: Control | D27: Common | E27: Screen & interaction | F27: 고객 서비스 분기 별 화면 구성 | G27: KR, EU | I27: 5 | J27: 1. CCS 이용불가 - 장애상황 | L27: 1. Control 진입 | M27: 1. 안전모드 (CCS 서버 장애) ※ 예외 : CCS 서버 장애 상태 Control 탭 진입 시 안전모드 제공 2. 안내문구 : 제한사유 3. 문 잠금 해제 / 문 잠금 | N27: =IF(COUNTIF(P27:W27,"F")>=1,"FAIL",(IF(COUNTIF(P27:W27,"P")>=1,"PASS",(IF(COUNTIF(P27:W27,"N/T")>=1,"N/T",(IF(COUNTIF(P27:W27,"N/A")>=1,"N/A","-"))))))) | O27: N/T | P27: N/T | T27: P | U27: =IF(COUNTIF(V27:W27,"F")>=1,"FAIL",(IF(COUNTIF(V27:W27,"P")>=1,"PASS",(IF(COUNTIF(V27:W27,"N/T")>=1,"N/T",(IF(COUNTIF(V27:W27,"N/A")>=1,"N/A","-"))))))) | V27: P | W27: P | X27: SPAQA-15249 SPAQA-15746 SPAQA-15747 SPAQA-15749 SPAQA-15742 SPAQA-17676 SPAQA-17046 SPAQA-17552 SPAQA-18124 SPAQA-19585 SPAQA-19847 SPAQA-20863 SPAQA-21972 SPAQA-20864 | Z27: ※안전모드 개발자 모드로 확인 가능 CCS 이용 불가 상황 필요
B28: TC_CT_1562 | C28: Control | D28: Intro | E28: 미가입 / 미로그인 / 신약관 | F28: 미가입 | G28: KR, EU | I28: 4 | J28: 1. 피공유자 상태 2. CCS 권한 없는 상태 | L28: 1. 주사용자 가 CCS 권한 X 1. 주사용자가 피공유자에게 CCS 권한없이 차량 공유 2. 피공유자 앱 확인 | M28: 1. Control 탭 미노출 되어야 함. | N28: =IF(COUNTIF(P28:W28,"F")>=1,"FAIL",(IF(COUNTIF(P28:W28,"P")>=1,"PASS",(IF(COUNTIF(P28:W28,"N/T")>=1,"N/T",(IF(COUNTIF(P28:W28,"N/A")>=1,"N/A","-"))))))) | O28: N/T | P28: N/T | T28: P | U28: =IF(COUNTIF(V28:W28,"F")>=1,"FAIL",(IF(COUNTIF(V28:W28,"P")>=1,"PASS",(IF(COUNTIF(V28:W28,"N/T")>=1,"N/T",(IF(COUNTIF(V28:W28,"N/A")>=1,"N/A","-"))))))) | V28: P | W28: P | X28: SPAQA-24596 | Y28: SPAQA-25635 | AB28: 수정
B29: TC_CT_1563 | C29: Control | D29: Intro | E29: 미가입 / 미로그인 / 신약관 | F29: 미가입 | G29: KR, EU | I29: 4 | J29: 1. 피공유자 상태 2. CCS 권한 있는 상태 3. 피 공유자 약관 동의 받은 상태 | L29: 1. 주사용자가 피공유자에게 CCS 권한 부여 2. 피공유자 계정으로 로그인 후 앱 확인 | M29: 1. Control 탭 노출 | N29: =IF(COUNTIF(P29:W29,"F")>=1,"FAIL",(IF(COUNTIF(P29:W29,"P")>=1,"PASS",(IF(COUNTIF(P29:W29,"N/T")>=1,"N/T",(IF(COUNTIF(P29:W29,"N/A")>=1,"N/A","-"))))))) | O29: N/T | P29: N/T | T29: P | U29: =IF(COUNTIF(V29:W29,"F")>=1,"FAIL",(IF(COUNTIF(V29:W29,"P")>=1,"PASS",(IF(COUNTIF(V29:W29,"N/T")>=1,"N/T",(IF(COUNTIF(V29:W29,"N/A")>=1,"N/A","-"))))))) | V29: P | W29: P | X29: SPAQA-24596 | AB29: 수정
B30: TC_CT_0005 | C30: Control | D30: Common | E30: Screen & interaction | F30: 제어 버튼 노출 방식 | G30: KR, EU | I30: 4 | K30: 1. MQTT 지원 | L30: 1. Control 진입 2. 메인 제어 버튼 확인 | M30: 1. 제어 버튼을 토글 형태로 제공(양방향) ex) ‘문 잠금 해제’ 제어 성공 시 '문 잠금 해제' 상태로 버튼 상태 변경 | N30: =IF(COUNTIF(P30:W30,"F")>=1,"FAIL",(IF(COUNTIF(P30:W30,"P")>=1,"PASS",(IF(COUNTIF(P30:W30,"N/T")>=1,"N/T",(IF(COUNTIF(P30:W30,"N/A")>=1,"N/A","-"))))))) | O30: N/T | P30: N/T | T30: P | U30: =IF(COUNTIF(V30:W30,"F")>=1,"FAIL",(IF(COUNTIF(V30:W30,"P")>=1,"PASS",(IF(COUNTIF(V30:W30,"N/T")>=1,"N/T",(IF(COUNTIF(V30:W30,"N/A")>=1,"N/A","-"))))))) | V30: P | W30: P | Z30: K : MV원격사용불가(방전)
B31: TC_CT_0006 | C31: Control | D31: Common | E31: Screen & interaction | F31: 제어 버튼 노출 방식 | G31: KR, EU | I31: 4 | K31: 1. MQTT 이전 | L31: 1. Control 진입 2. 메인 제어 버튼 확인 | M31: 1. 제어 버튼을 팝업 형태로 제공(단방향) - 차량 현재 상태값을 알 수 없기 때문에 모두 제공) | N31: =IF(COUNTIF(P31:W31,"F")>=1,"FAIL",(IF(COUNTIF(P31:W31,"P")>=1,"PASS",(IF(COUNTIF(P31:W31,"N/T")>=1,"N/T",(IF(COUNTIF(P31:W31,"N/A")>=1,"N/A","-"))))))) | O31: N/T | P31: N/T | T31: P | U31: =IF(COUNTIF(V31:W31,"F")>=1,"FAIL",(IF(COUNTIF(V31:W31,"P")>=1,"PASS",(IF(COUNTIF(V31:W31,"N/T")>=1,"N/T",(IF(COUNTIF(V31:W31,"N/A")>=1,"N/A","-"))))))) | V31: P | W31: P
B32: TC_CT_0007 | C32: Control | D32: Common | E32: Screen & interaction | F32: 서브 제어 동작 사양 | G32: KR, EU | I32: 4 | L32: 1. Control 진입 2. 제어 진입 3. 서브 제어 버튼 선택 4. 차량 이미지 선택 | M32: 1. sub tab 닫힘 | N32: =IF(COUNTIF(P32:W32,"F")>=1,"FAIL",(IF(COUNTIF(P32:W32,"P")>=1,"PASS",(IF(COUNTIF(P32:W32,"N/T")>=1,"N/T",(IF(COUNTIF(P32:W32,"N/A")>=1,"N/A","-"))))))) | O32: N/T | P32: N/T | T32: P | U32: =IF(COUNTIF(V32:W32,"F")>=1,"FAIL",(IF(COUNTIF(V32:W32,"P")>=1,"PASS",(IF(COUNTIF(V32:W32,"N/T")>=1,"N/T",(IF(COUNTIF(V32:W32,"N/A")>=1,"N/A","-"))))))) | V32: P | W32: P
B33: TC_CT_0008 | C33: Control | D33: Common | E33: Screen & interaction | F33: 서브 제어 동작 사양 | G33: KR, EU | I33: 4 | L33: 1. Control 진입 2. 제어 진입 3. 서브 제어 버튼 선택 4. 서브 제어 영역 swipe to right | M33: 1. sub tab 닫힘 | N33: =IF(COUNTIF(P33:W33,"F")>=1,"FAIL",(IF(COUNTIF(P33:W33,"P")>=1,"PASS",(IF(COUNTIF(P33:W33,"N/T")>=1,"N/T",(IF(COUNTIF(P33:W33,"N/A")>=1,"N/A","-"))))))) | O33: N/T | P33: N/T | T33: P | U33: =IF(COUNTIF(V33:W33,"F")>=1,"FAIL",(IF(COUNTIF(V33:W33,"P")>=1,"PASS",(IF(COUNTIF(V33:W33,"N/T")>=1,"N/T",(IF(COUNTIF(V33:W33,"N/A")>=1,"N/A","-"))))))) | V33: P | W33: P
B34: TC_CT_0009 | C34: Control | D34: Common | E34: Screen & interaction | F34: 서브 제어 동작 사양 | G34: KR, EU | I34: 4 | L34: 1. Control 진입 2. 제어 진입 3. 서브 제어 버튼 선택 4. 선택한 서브 제어 버튼 재선택 | M34: 1. sub tab 닫힘 | N34: =IF(COUNTIF(P34:W34,"F")>=1,"FAIL",(IF(COUNTIF(P34:W34,"P")>=1,"PASS",(IF(COUNTIF(P34:W34,"N/T")>=1,"N/T",(IF(COUNTIF(P34:W34,"N/A")>=1,"N/A","-"))))))) | O34: N/T | P34: N/T | T34: P | U34: =IF(COUNTIF(V34:W34,"F")>=1,"FAIL",(IF(COUNTIF(V34:W34,"P")>=1,"PASS",(IF(COUNTIF(V34:W34,"N/T")>=1,"N/T",(IF(COUNTIF(V34:W34,"N/A")>=1,"N/A","-"))))))) | V34: P | W34: P
B35: TC_CT_0010 | C35: Control | D35: Common | E35: Screen & interaction | F35: 서브 제어 동작 사양 | G35: KR, EU | I35: 4 | J35: 1. iOS Only | L35: 1. Control 진입 2. 제어 진입 3. 서브 제어 버튼 선택 4. 빈 영역 선택 | M35: 1. sub tab 닫힘 | N35: =IF(COUNTIF(P35:W35,"F")>=1,"FAIL",(IF(COUNTIF(P35:W35,"P")>=1,"PASS",(IF(COUNTIF(P35:W35,"N/T")>=1,"N/T",(IF(COUNTIF(P35:W35,"N/A")>=1,"N/A","-"))))))) | O35: N/T | P35: N/T | T35: P | U35: =IF(COUNTIF(V35:W35,"F")>=1,"FAIL",(IF(COUNTIF(V35:W35,"P")>=1,"PASS",(IF(COUNTIF(V35:W35,"N/T")>=1,"N/T",(IF(COUNTIF(V35:W35,"N/A")>=1,"N/A","-"))))))) | V35: N/A | W35: P
B36: TC_CT_0011 | C36: Control | D36: Common | E36: Screen & interaction | F36: 서브 제어 동작 사양 | G36: KR, EU | I36: 4 | J36: 1. 예외 Case - Z Fold 1. 대화면 폼팩터 단말(Android) ex) Z Fold 단말 | L36: 1. Control 진입 2. 제어 진입 3. 서브 제어 버튼 선택 4. 차량 이미지 선택 | M36: 1. 차량 상태 상세로 이동 | N36: =IF(COUNTIF(P36:W36,"F")>=1,"FAIL",(IF(COUNTIF(P36:W36,"P")>=1,"PASS",(IF(COUNTIF(P36:W36,"N/T")>=1,"N/T",(IF(COUNTIF(P36:W36,"N/A")>=1,"N/A","-"))))))) | O36: N/T | P36: N/T | T36: N/A | U36: =IF(COUNTIF(V36:W36,"F")>=1,"FAIL",(IF(COUNTIF(V36:W36,"P")>=1,"PASS",(IF(COUNTIF(V36:W36,"N/T")>=1,"N/T",(IF(COUNTIF(V36:W36,"N/A")>=1,"N/A","-"))))))) | V36: P | W36: N/A | AB36: 수정
B37: TC_CT_1564 | C37: Control | D37: Common | E37: Screen & interaction | F37: 서브 제어 동작 사양 | G37: KR, EU | I37: 4 | J37: 1. 예외 Case - Z Fold 1. 대화면 폼팩터 단말(Android) ex) Z Fold 단말 | L37: 1. Control 진입 2. 제어 진입 3. 서브 제어 버튼 선택 4. 서브 제어 영역 내에서 Swipe to right 동작 | M37: 1. Sub tab 닫힘 | N37: =IF(COUNTIF(P37:W37,"F")>=1,"FAIL",(IF(COUNTIF(P37:W37,"P")>=1,"PASS",(IF(COUNTIF(P37:W37,"N/T")>=1,"N/T",(IF(COUNTIF(P37:W37,"N/A")>=1,"N/A","-"))))))) | O37: N/T | P37: N/T | T37: N/A | U37: =IF(COUNTIF(V37:W37,"F")>=1,"FAIL",(IF(COUNTIF(V37:W37,"P")>=1,"PASS",(IF(COUNTIF(V37:W37,"N/T")>=1,"N/T",(IF(COUNTIF(V37:W37,"N/A")>=1,"N/A","-"))))))) | V37: P | W37: N/A | AB37: 수정
B38: TC_CT_1565 | C38: Control | D38: Common | E38: Screen & interaction | F38: 서브 제어 동작 사양 | G38: KR, EU | I38: 4 | J38: 1. 예외 Case - Z Fold 1. 대화면 폼팩터 단말(Android) ex) Z Fold 단말 | L38: 1. Control 진입 2. 제어 진입 3. 서브 제어 버튼 선택 4. 선택한 서브 제어 버튼 재선택 | M38: 3. Sub tab 닫힘 | N38: =IF(COUNTIF(P38:W38,"F")>=1,"FAIL",(IF(COUNTIF(P38:W38,"P")>=1,"PASS",(IF(COUNTIF(P38:W38,"N/T")>=1,"N/T",(IF(COUNTIF(P38:W38,"N/A")>=1,"N/A","-"))))))) | O38: N/T | P38: N/T | T38: N/A | U38: =IF(COUNTIF(V38:W38,"F")>=1,"FAIL",(IF(COUNTIF(V38:W38,"P")>=1,"PASS",(IF(COUNTIF(V38:W38,"N/T")>=1,"N/T",(IF(COUNTIF(V38:W38,"N/A")>=1,"N/A","-"))))))) | V38: P | W38: N/A | AB38: 수정
B39: TC_CT_1558 | C39: Control | D39: Common | E39: Screen & interaction | F39: 서브 제어 동작 사양 | G39: KR, EU | I39: 4 | J39: 1. Android Only | L39: 1. Control 진입 2. 서브 제어 버튼 선택하여 Sub tab 열기 3. OS back key 선택 | M39: 1. Sub tab 닫힘 | N39: =IF(COUNTIF(P39:W39,"F")>=1,"FAIL",(IF(COUNTIF(P39:W39,"P")>=1,"PASS",(IF(COUNTIF(P39:W39,"N/T")>=1,"N/T",(IF(COUNTIF(P39:W39,"N/A")>=1,"N/A","-"))))))) | O39: N/T | P39: N/T | T39: N/A | U39: =IF(COUNTIF(V39:W39,"F")>=1,"FAIL",(IF(COUNTIF(V39:W39,"P")>=1,"PASS",(IF(COUNTIF(V39:W39,"N/T")>=1,"N/T",(IF(COUNTIF(V39:W39,"N/A")>=1,"N/A","-"))))))) | V39: P | W39: N/A
B40: TC_CT_0012 | C40: Control | D40: Common | E40: Screen & interaction | F40: 서브 제어 동작 사양 | G40: KR, EU | I40: 4 | L40: 1. Control 진입 2. 제어 진입 3. 서브 제어 버튼 선택하여 탭 표출 4. 화면 위,아래로 스크롤 동작 | M40: 1. 서브 제어 메뉴 포커스 유지 | N40: =IF(COUNTIF(P40:W40,"F")>=1,"FAIL",(IF(COUNTIF(P40:W40,"P")>=1,"PASS",(IF(COUNTIF(P40:W40,"N/T")>=1,"N/T",(IF(COUNTIF(P40:W40,"N/A")>=1,"N/A","-"))))))) | O40: N/T | P40: N/T | T40: P | U40: =IF(COUNTIF(V40:W40,"F")>=1,"FAIL",(IF(COUNTIF(V40:W40,"P")>=1,"PASS",(IF(COUNTIF(V40:W40,"N/T")>=1,"N/T",(IF(COUNTIF(V40:W40,"N/A")>=1,"N/A","-"))))))) | V40: P | W40: P | X40: SPAQA-12676
B41: TC_CT_1566 | C41: Control | D41: Common | E41: Screen & interaction | F41: 서브 제어 동작 사양 | G41: KR, EU | I41: 4 | L41: 1. Control 진입 2. 제어 진입 3. 서브 제어 버튼 선택하여 탭 표출 4. 다른 탭 이동 후 재진입(ex MyCar 이동 후, Control 재진입) | M41: 1. 서브 제어 메뉴 포커스 유지 | N41: =IF(COUNTIF(P41:W41,"F")>=1,"FAIL",(IF(COUNTIF(P41:W41,"P")>=1,"PASS",(IF(COUNTIF(P41:W41,"N/T")>=1,"N/T",(IF(COUNTIF(P41:W41,"N/A")>=1,"N/A","-"))))))) | O41: N/T | P41: N/T | T41: P | U41: =IF(COUNTIF(V41:W41,"F")>=1,"FAIL",(IF(COUNTIF(V41:W41,"P")>=1,"PASS",(IF(COUNTIF(V41:W41,"N/T")>=1,"N/T",(IF(COUNTIF(V41:W41,"N/A")>=1,"N/A","-"))))))) | V41: P | W41: P
B42: TC_CT_0013 | C42: Control | D42: Common | E42: Screen & interaction | F42: 서브 제어 동작 사양 | G42: KR, EU | I42: 4 | K42: 1. 서브 제어 탭 : 창문, 환기, 커튼 있는 차량 | L42: 1. Control 진입 2. 제어 진입 3. 창문/ 커튼 제어 버튼 선택 | M42: 1. “창문 열기” or “환기하기” 제어 성공 시, 창문 열림 상태로 전환 2. “창문 닫기” or “커튼 올림” 제어 성공 시, 창문 닫힘 상태로 전환 | N42: =IF(COUNTIF(P42:W42,"F")>=1,"FAIL",(IF(COUNTIF(P42:W42,"P")>=1,"PASS",(IF(COUNTIF(P42:W42,"N/T")>=1,"N/T",(IF(COUNTIF(P42:W42,"N/A")>=1,"N/A","-"))))))) | O42: N/T | P42: N/T | T42: N/A | U42: =IF(COUNTIF(V42:W42,"F")>=1,"FAIL",(IF(COUNTIF(V42:W42,"P")>=1,"PASS",(IF(COUNTIF(V42:W42,"N/T")>=1,"N/T",(IF(COUNTIF(V42:W42,"N/A")>=1,"N/A","-"))))))) | V42: N/A | W42: N/A | X42: SPAQA-13307 SPAQA-16661 | Z42: 내용 중복으로 TC 삭제 | AA42: 사양 아님(N/A) | AB42: 삭제
...

Sheet Map
C1: TC 추가 NO : | D1: =IFERROR(__xludf.DUMMYFUNCTION("""TC_""&""MAP""&""_""&TEXT(ARRAYFORMULA(MAX(IFERROR(VALUE(REGEXEXTRACT(B294:B1650, ""\d+"")))))+1,""0000"")"),"TC_MAP_1606")
B2: CCI One App | E2: EU FullTC | L2: =Control!L2 | M2: =IF(COUNTIF(N2:O2,"F")>=1,"FAIL",(IF(COUNTIF(N2:O2,"P")>=1,"PASS",(IF(COUNTIF(N2:O2,"N/T")>=1,"N/T",(IF(COUNTIF(N2:O2,"N/A")>=1,"N/A","-"))))))) | O2: 추가 | P2: 수정 | Q2: 삭제
E3: Project | H3: UID ver. | J3: 1월 피쳐컷 | L3: =Control!L3 | M3: =IF(COUNTIF(N3:O3,"F")>=1,"FAIL",(IF(COUNTIF(N3:O3,"P")>=1,"PASS",(IF(COUNTIF(N3:O3,"N/T")>=1,"N/T",(IF(COUNTIF(N3:O3,"N/A")>=1,"N/A","-"))))))) | O3: =COUNTIFS($AB:$AB,"*"&O2&"*") | P3: =COUNTIFS($AB:$AB,"*"&P2&"*") | Q3: =COUNTIFS($AB:$AB,"*"&Q2&"*")
E4: 담당자 | H4: 작성일자 | L4: =Control!L4 | M4: =IF(COUNTIF(N4:O4,"F")>=1,"FAIL",(IF(COUNTIF(N4:O4,"P")>=1,"PASS",(IF(COUNTIF(N4:O4,"N/T")>=1,"N/T",(IF(COUNTIF(N4:O4,"N/A")>=1,"N/A","-")))))))
L5: =Control!L5 | M5: =IF(COUNTIF(N5:O5,"F")>=1,"FAIL",(IF(COUNTIF(N5:O5,"P")>=1,"PASS",(IF(COUNTIF(N5:O5,"N/T")>=1,"N/T",(IF(COUNTIF(N5:O5,"N/A")>=1,"N/A","-"))))))) | N5: ← 색깔 업뎃 시 직접 색 지정하지 말고, 이거 복붙해 주세요(누가 처리 했는지 히스토리 보관용)
B6: 테스트 환경
B7: Tester
B9: Test Target | D9: Total TC | E9: RunRate | F9: PassRate | G9: PASS | H9: FAIL | I9: N/A | J9: N/T | N9: Brand | O9: KOA | R9: HOA | U9: GOA
B10: Total | D10: =SUM(D11:D25) | E10: =IFERROR(SUM($G10:J10)/$D10,"-") | F10: =IFERROR($G10/(SUM(G10:H10)),"-") | G10: =SUM(G11:G25) | H10: =SUM(H11:H25) | I10: =SUM(I11:I25) | J10: =SUM(J11:J25) | N10: OS 별 결과 | O10: Total | P10: Android | Q10: iOS | R10: Total | S10: Android | T10: iOS | U10: Total | V10: Android | W10: iOS
B11: Map | C11: Common | D11: =COUNTIF($D$29:$D$6877,$C11) | E11: =IFERROR(SUM($G11:J11)/$D11,"-") | F11: =IFERROR($G11/(SUM(G11:H11)),"-") | G11: =COUNTIFS($D:$D,$C11,$N:$N,G$9) | H11: =COUNTIFS($D:$D,$C11,$N:$N,H$9) | I11: =COUNTIFS($D:$D,$C11,$N:$N,I$9) | J11: =COUNTIFS($D:$D,$C11,$N:$N,J$9) | N11: Total | O11: =SUM(O12:O15) | P11: =SUM(P12:P15) | Q11: =SUM(Q12:Q15) | R11: =SUM(R12:R15) | S11: =SUM(S12:S15) | T11: =SUM(T12:T15) | U11: =SUM(U12:U15) | V11: =SUM(V12:V15) | W11: =SUM(W12:W15)
C12: Common (폴리엇 기준) | D12: =COUNTIF($D$29:$D$6877,$C12) | E12: =IFERROR(SUM($G12:J12)/$D12,"-") | F12: =IFERROR($G12/(SUM(G12:H12)),"-") | G12: =COUNTIFS($D:$D,$C12,$N:$N,G$9) | H12: =COUNTIFS($D:$D,$C12,$N:$N,H$9) | I12: =COUNTIFS($D:$D,$C12,$N:$N,I$9) | J12: =COUNTIFS($D:$D,$C12,$N:$N,J$9) | N12: PASS | O12: =COUNTIFS(O$28:O$10284,$N12) | P12: =COUNTIFS(P$28:P$10284,"P") | Q12: =COUNTIFS(Q$28:Q$10284,"P") | R12: =COUNTIFS(R$28:R$10284,$N12) | S12: =COUNTIFS(S$28:S$10284,"P") | T12: =COUNTIFS(T$28:T$10284,"P") | U12: =COUNTIFS(U$28:U$10284,$N12) | V12: =COUNTIFS(V$28:V$10284,"P") | W12: =COUNTIFS(W$28:W$10284,"P")
C13: 화면 분기 | D13: =COUNTIF($D$29:$D$6877,$C13) | E13: =IFERROR(SUM($G13:J13)/$D13,"-") | F13: =IFERROR($G13/(SUM(G13:H13)),"-") | G13: =COUNTIFS($D:$D,$C13,$N:$N,G$9) | H13: =COUNTIFS($D:$D,$C13,$N:$N,H$9) | I13: =COUNTIFS($D:$D,$C13,$N:$N,I$9) | J13: =COUNTIFS($D:$D,$C13,$N:$N,J$9) | N13: FAIL | O13: =COUNTIFS(O$27:O$10283,$N13) | P13: =COUNTIFS(P$27:P$10283,"F") | Q13: =COUNTIFS(Q$27:Q$10283,"F") | R13: =COUNTIFS(R$27:R$10283,$N13) | S13: =COUNTIFS(S$27:S$10283,"F") | T13: =COUNTIFS(T$27:T$10283,"F") | U13: =COUNTIFS(U$27:U$10283,$N13) | V13: =COUNTIFS(V$27:V$10283,"F") | W13: =COUNTIFS(W$27:W$10283,"F")
C14: 메인 지도 | D14: =COUNTIF($D$29:$D$6877,$C14) | E14: =IFERROR(SUM($G14:J14)/$D14,"-") | F14: =IFERROR($G14/(SUM(G14:H14)),"-") | G14: =COUNTIFS($D:$D,$C14,$N:$N,G$9) | H14: =COUNTIFS($D:$D,$C14,$N:$N,H$9) | I14: =COUNTIFS($D:$D,$C14,$N:$N,I$9) | J14: =COUNTIFS($D:$D,$C14,$N:$N,J$9) | N14: N/A | O14: =COUNTIFS(O$27:O$10283,$N14) | P14: =COUNTIFS(P$27:P$10283,$N14) | Q14: =COUNTIFS(Q$27:Q$10283,$N14) | R14: =COUNTIFS(R$27:R$10283,$N14) | S14: =COUNTIFS(S$27:S$10283,"N/A") | T14: =COUNTIFS(T$27:T$10283,"N/A") | U14: =COUNTIFS(U$27:U$10283,$N14) | V14: =COUNTIFS(V$27:V$10283,"N/A") | W14: =COUNTIFS(W$27:W$10283,"N/A")
C15: 홈 탭 | D15: =COUNTIF($D$29:$D$6877,$C15) | E15: =IFERROR(SUM($G15:J15)/$D15,"-") | F15: =IFERROR($G15/(SUM(G15:H15)),"-") | G15: =COUNTIFS($D:$D,$C15,$N:$N,G$9) | H15: =COUNTIFS($D:$D,$C15,$N:$N,H$9) | I15: =COUNTIFS($D:$D,$C15,$N:$N,I$9) | J15: =COUNTIFS($D:$D,$C15,$N:$N,J$9) | N15: N/T | O15: =COUNTIFS(O$27:O$10283,$N15) | P15: =COUNTIFS(P$27:P$10283,$N15) | Q15: =COUNTIFS(Q$27:Q$10283,$N15) | R15: =COUNTIFS(R$27:R$10283,$N15) | S15: =COUNTIFS(S$27:S$10283,"N/T") | T15: =COUNTIFS(T$27:T$10283,"N/T") | U15: =COUNTIFS(U$27:U$10283,$N15) | V15: =COUNTIFS(V$27:V$10283,"N/T") | W15: =COUNTIFS(W$27:W$10283,"N/T")
C16: 즐겨찾기 탭 | D16: =COUNTIF($D$29:$D$6877,$C16) | E16: =IFERROR(SUM($G16:J16)/$D16,"-") | F16: =IFERROR($G16/(SUM(G16:H16)),"-") | G16: =COUNTIFS($D:$D,$C16,$N:$N,G$9) | H16: =COUNTIFS($D:$D,$C16,$N:$N,H$9) | I16: =COUNTIFS($D:$D,$C16,$N:$N,I$9) | J16: =COUNTIFS($D:$D,$C16,$N:$N,J$9)
C17: 최근 검색 탭 | D17: =COUNTIF($D$29:$D$6877,$C17) | E17: =IFERROR(SUM($G17:J17)/$D17,"-") | F17: =IFERROR($G17/(SUM(G17:H17)),"-") | G17: =COUNTIFS($D:$D,$C17,$N:$N,G$9) | H17: =COUNTIFS($D:$D,$C17,$N:$N,H$9) | I17: =COUNTIFS($D:$D,$C17,$N:$N,I$9) | J17: =COUNTIFS($D:$D,$C17,$N:$N,J$9)
C18: 장소/주소 검색 | D18: =COUNTIF($D$29:$D$6877,$C18) | E18: =IFERROR(SUM($G18:J18)/$D18,"-") | F18: =IFERROR($G18/(SUM(G18:H18)),"-") | G18: =COUNTIFS($D:$D,$C18,$N:$N,G$9) | H18: =COUNTIFS($D:$D,$C18,$N:$N,H$9) | I18: =COUNTIFS($D:$D,$C18,$N:$N,I$9) | J18: =COUNTIFS($D:$D,$C18,$N:$N,J$9)
C19: 주변 검색 | D19: =COUNTIF($D$29:$D$6877,$C19) | E19: =IFERROR(SUM($G19:J19)/$D19,"-") | F19: =IFERROR($G19/(SUM(G19:H19)),"-") | G19: =COUNTIFS($D:$D,$C19,$N:$N,G$9) | H19: =COUNTIFS($D:$D,$C19,$N:$N,H$9) | I19: =COUNTIFS($D:$D,$C19,$N:$N,I$9) | J19: =COUNTIFS($D:$D,$C19,$N:$N,J$9)
C20: POI 상세 | D20: =COUNTIF($D$29:$D$6877,$C20) | E20: =IFERROR(SUM($G20:J20)/$D20,"-") | F20: =IFERROR($G20/(SUM(G20:H20)),"-") | G20: =COUNTIFS($D:$D,$C20,$N:$N,G$9) | H20: =COUNTIFS($D:$D,$C20,$N:$N,H$9) | I20: =COUNTIFS($D:$D,$C20,$N:$N,I$9) | J20: =COUNTIFS($D:$D,$C20,$N:$N,J$9)
C21: 경로 탐색 | D21: =COUNTIF($D$29:$D$6877,$C21) | E21: =IFERROR(SUM($G21:J21)/$D21,"-") | F21: =IFERROR($G21/(SUM(G21:H21)),"-") | G21: =COUNTIFS($D:$D,$C21,$N:$N,G$9) | H21: =COUNTIFS($D:$D,$C21,$N:$N,H$9) | I21: =COUNTIFS($D:$D,$C21,$N:$N,I$9) | J21: =COUNTIFS($D:$D,$C21,$N:$N,J$9)
C22: 내 차 위치 | D22: =COUNTIF($D$29:$D$6877,$C22) | E22: =IFERROR(SUM($G22:J22)/$D22,"-") | F22: =IFERROR($G22/(SUM(G22:H22)),"-") | G22: =COUNTIFS($D:$D,$C22,$N:$N,G$9) | H22: =COUNTIFS($D:$D,$C22,$N:$N,H$9) | I22: =COUNTIFS($D:$D,$C22,$N:$N,I$9) | J22: =COUNTIFS($D:$D,$C22,$N:$N,J$9)
C23: 최종 목적지 안내 | D23: =COUNTIF($D$29:$D$6877,$C23) | E23: =IFERROR(SUM($G23:J23)/$D23,"-") | F23: =IFERROR($G23/(SUM(G23:H23)),"-") | G23: =COUNTIFS($D:$D,$C23,$N:$N,G$9) | H23: =COUNTIFS($D:$D,$C23,$N:$N,H$9) | I23: =COUNTIFS($D:$D,$C23,$N:$N,I$9) | J23: =COUNTIFS($D:$D,$C23,$N:$N,J$9)
C24: 발레 모드 | D24: =COUNTIF($D$29:$D$6877,$C24) | E24: =IFERROR(SUM($G24:J24)/$D24,"-") | F24: =IFERROR($G24/(SUM(G24:H24)),"-") | G24: =COUNTIFS($D:$D,$C24,$N:$N,G$9) | H24: =COUNTIFS($D:$D,$C24,$N:$N,H$9) | I24: =COUNTIFS($D:$D,$C24,$N:$N,I$9) | J24: =COUNTIFS($D:$D,$C24,$N:$N,J$9)
C25: 외부 맵 S2C 요청 (OS Share) | D25: =COUNTIF($D$29:$D$6877,$C25) | E25: =IFERROR(SUM($G25:J25)/$D25,"-") | F25: =IFERROR($G25/(SUM(G25:H25)),"-") | G25: =COUNTIFS($D:$D,$C25,$N:$N,G$9) | H25: =COUNTIFS($D:$D,$C25,$N:$N,H$9) | I25: =COUNTIFS($D:$D,$C25,$N:$N,I$9) | J25: =COUNTIFS($D:$D,$C25,$N:$N,J$9)
B27: TC ID | C27: 카테고리 | D27: 대분류 | E27: 중분류 | F27: 소분류 | G27: 향지 | H27: 브랜드 | I27: 우선순위 | J27: Pre-condition | L27: TC procedure | M27: Expected result | N27: Result | O27: KOA Result | P27: KOA | R27: HOA Result | S27: HOA | U27: GOA Result | V27: GOA | X27: Closed 지라 NO | Y27: 지라 NO. | Z27: NT/NA 상세 사유 | AA27: N/A N/T 필터 | AB27: LABEL
J28: App 동작 조건 | K28: 차량 동작 조건 | P28: Android | Q28: iOS | S28: Android | T28: iOS | V28: Android | W28: iOS
B29: TC_MAP_0001 | C29: Map | D29: Common | E29: 지도 정보 표시 | F29: 로고 | G29: EU | I29: 4 | J29: 1. Here 맵 | L29: 1. Map 진입 2. 드로어 최소화 3. 지도 확인 | M29: 1. 지도 좌하단에 Here 로고 노출 | N29: =IF(COUNTIF(P29:W29,"F")>=1,"FAIL",(IF(COUNTIF(P29:W29,"P")>=1,"PASS",(IF(COUNTIF(P29:W29,"N/T")>=1,"N/T",(IF(COUNTIF(P29:W29,"N/A")>=1,"N/A","-"))))))) | O29: =IF(COUNTIF(P29:Q29,"F")>=1,"FAIL",(IF(COUNTIF(P29:Q29,"P")>=1,"PASS",(IF(COUNTIF(P29:Q29,"N/T")>=1,"N/T",(IF(COUNTIF(P29:Q29,"N/A")>=1,"N/A","-"))))))) | P29: P | Q29: P | R29: =IF(COUNTIF(S29:T29,"F")>=1,"FAIL",(IF(COUNTIF(S29:T29,"P")>=1,"PASS",(IF(COUNTIF(S29:T29,"N/T")>=1,"N/T",(IF(COUNTIF(S29:T29,"N/A")>=1,"N/A","-"))))))) | S29: P | T29: P | U29: =IF(COUNTIF(V29:W29,"F")>=1,"FAIL",(IF(COUNTIF(V29:W29,"P")>=1,"PASS",(IF(COUNTIF(V29:W29,"N/T")>=1,"N/T",(IF(COUNTIF(V29:W29,"N/A")>=1,"N/A","-"))))))) | V29: P | W29: P | X29: SPAQA-23885 SPAQA-25036 SPAQA-26158 SPAQA-26160
B30: TC_MAP_0002 | C30: Map | D30: Common | E30: 지도 정보 표시 | F30: 로고 | G30: EU | I30: 4 | J30: 1. Here 맵 | L30: 1. Map 진입 2. 드로어 확장 3. 지도 확인 | M30: 1. Here 로고가 Bottom Sheet에 가려짐 | N30: =IF(COUNTIF(P30:W30,"F")>=1,"FAIL",(IF(COUNTIF(P30:W30,"P")>=1,"PASS",(IF(COUNTIF(P30:W30,"N/T")>=1,"N/T",(IF(COUNTIF(P30:W30,"N/A")>=1,"N/A","-"))))))) | O30: =IF(COUNTIF(P30:Q30,"F")>=1,"FAIL",(IF(COUNTIF(P30:Q30,"P")>=1,"PASS",(IF(COUNTIF(P30:Q30,"N/T")>=1,"N/T",(IF(COUNTIF(P30:Q30,"N/A")>=1,"N/A","-"))))))) | P30: P | Q30: P | R30: =IF(COUNTIF(S30:T30,"F")>=1,"FAIL",(IF(COUNTIF(S30:T30,"P")>=1,"PASS",(IF(COUNTIF(S30:T30,"N/T")>=1,"N/T",(IF(COUNTIF(S30:T30,"N/A")>=1,"N/A","-"))))))) | S30: P | T30: P | U30: =IF(COUNTIF(V30:W30,"F")>=1,"FAIL",(IF(COUNTIF(V30:W30,"P")>=1,"PASS",(IF(COUNTIF(V30:W30,"N/T")>=1,"N/T",(IF(COUNTIF(V30:W30,"N/A")>=1,"N/A","-"))))))) | V30: P | W30: P
A31: R_179 | B31: TC_MAP_0003 | C31: Map | D31: Common | E31: 지도 정보 표시 | F31: 로고 | G31: EU | I31: 4 | J31: 1. Google 맵 | L31: 1. Map 진입 2. 드로어 최소화 3. 지도 확인 | M31: 1. Bottom Sheet 좌상단에 Google 로고 노출 | N31: =IF(COUNTIF(P31:W31,"F")>=1,"FAIL",(IF(COUNTIF(P31:W31,"P")>=1,"PASS",(IF(COUNTIF(P31:W31,"N/T")>=1,"N/T",(IF(COUNTIF(P31:W31,"N/A")>=1,"N/A","-"))))))) | O31: =IF(COUNTIF(P31:Q31,"F")>=1,"FAIL",(IF(COUNTIF(P31:Q31,"P")>=1,"PASS",(IF(COUNTIF(P31:Q31,"N/T")>=1,"N/T",(IF(COUNTIF(P31:Q31,"N/A")>=1,"N/A","-"))))))) | P31: P | Q31: P | R31: =IF(COUNTIF(S31:T31,"F")>=1,"FAIL",(IF(COUNTIF(S31:T31,"P")>=1,"PASS",(IF(COUNTIF(S31:T31,"N/T")>=1,"N/T",(IF(COUNTIF(S31:T31,"N/A")>=1,"N/A","-"))))))) | S31: P | T31: P | U31: =IF(COUNTIF(V31:W31,"F")>=1,"FAIL",(IF(COUNTIF(V31:W31,"P")>=1,"PASS",(IF(COUNTIF(V31:W31,"N/T")>=1,"N/T",(IF(COUNTIF(V31:W31,"N/A")>=1,"N/A","-"))))))) | V31: P | W31: P | X31: SPAQA-22906 SPAQA-22912 SPAQA-22373 SPAQA-26160 SPAQA-26431 | AB31: TASK
B32: TC_MAP_0004 | C32: Map | D32: Common | E32: 지도 정보 표시 | F32: 로고 | G32: EU | I32: 4 | J32: 1. Google 맵 | L32: 1. Map 진입 2. 드로어 확장 3. 지도 확인 | M32: 1. Google 로고가 Bottom Sheet를 따라 좌상단 노출 유지 됨 | N32: =IF(COUNTIF(P32:W32,"F")>=1,"FAIL",(IF(COUNTIF(P32:W32,"P")>=1,"PASS",(IF(COUNTIF(P32:W32,"N/T")>=1,"N/T",(IF(COUNTIF(P32:W32,"N/A")>=1,"N/A","-"))))))) | O32: =IF(COUNTIF(P32:Q32,"F")>=1,"FAIL",(IF(COUNTIF(P32:Q32,"P")>=1,"PASS",(IF(COUNTIF(P32:Q32,"N/T")>=1,"N/T",(IF(COUNTIF(P32:Q32,"N/A")>=1,"N/A","-"))))))) | P32: P | Q32: P | R32: =IF(COUNTIF(S32:T32,"F")>=1,"FAIL",(IF(COUNTIF(S32:T32,"P")>=1,"PASS",(IF(COUNTIF(S32:T32,"N/T")>=1,"N/T",(IF(COUNTIF(S32:T32,"N/A")>=1,"N/A","-"))))))) | S32: P | T32: P | U32: =IF(COUNTIF(V32:W32,"F")>=1,"FAIL",(IF(COUNTIF(V32:W32,"P")>=1,"PASS",(IF(COUNTIF(V32:W32,"N/T")>=1,"N/T",(IF(COUNTIF(V32:W32,"N/A")>=1,"N/A","-"))))))) | V32: P | W32: P | X32: SPAQA-22906 SPAQA-22912 SPAQA-22373 SPAQA-26242 | AB32: TASK
B33: TC_MAP_0005 | C33: Map | D33: Common | E33: 지도 정보 표시 | F33: 로고 | G33: EU | I33: 4 | L33: 1. Map 진입 2. 임의의 Poi 전체 상세 화면 진입 3. 상세 화면 내 미니맵 확인 | M33: 1. 미니맵 좌 하단에 로고 노출 | N33: =IF(COUNTIF(P33:W33,"F")>=1,"FAIL",(IF(COUNTIF(P33:W33,"P")>=1,"PASS",(IF(COUNTIF(P33:W33,"N/T")>=1,"N/T",(IF(COUNTIF(P33:W33,"N/A")>=1,"N/A","-"))))))) | O33: =IF(COUNTIF(P33:Q33,"F")>=1,"FAIL",(IF(COUNTIF(P33:Q33,"P")>=1,"PASS",(IF(COUNTIF(P33:Q33,"N/T")>=1,"N/T",(IF(COUNTIF(P33:Q33,"N/A")>=1,"N/A","-"))))))) | P33: P | Q33: P | R33: =IF(COUNTIF(S33:T33,"F")>=1,"FAIL",(IF(COUNTIF(S33:T33,"P")>=1,"PASS",(IF(COUNTIF(S33:T33,"N/T")>=1,"N/T",(IF(COUNTIF(S33:T33,"N/A")>=1,"N/A","-"))))))) | S33: P | T33: P | U33: =IF(COUNTIF(V33:W33,"F")>=1,"FAIL",(IF(COUNTIF(V33:W33,"P")>=1,"PASS",(IF(COUNTIF(V33:W33,"N/T")>=1,"N/T",(IF(COUNTIF(V33:W33,"N/A")>=1,"N/A","-"))))))) | V33: P | W33: P
B34: TC_MAP_0006 | C34: Map | D34: Common | E34: 지도 재진입 | F34: 지도 재진입 | G34: KR, EU, NA | I34: 4 | J34: 1. 내 차 위치 조회 가능할 경우 | L34: 1. Map 진입 2. 메인 지도 확인 | M34: 1. 내 차 위치 마커 포커스 2. Default 줌레벨로 원복 | N34: =IF(COUNTIF(P34:W34,"F")>=1,"FAIL",(IF(COUNTIF(P34:W34,"P")>=1,"PASS",(IF(COUNTIF(P34:W34,"N/T")>=1,"N/T",(IF(COUNTIF(P34:W34,"N/A")>=1,"N/A","-"))))))) | O34: =IF(COUNTIF(P34:Q34,"F")>=1,"FAIL",(IF(COUNTIF(P34:Q34,"P")>=1,"PASS",(IF(COUNTIF(P34:Q34,"N/T")>=1,"N/T",(IF(COUNTIF(P34:Q34,"N/A")>=1,"N/A","-"))))))) | P34: P | Q34: P | R34: =IF(COUNTIF(S34:T34,"F")>=1,"FAIL",(IF(COUNTIF(S34:T34,"P")>=1,"PASS",(IF(COUNTIF(S34:T34,"N/T")>=1,"N/T",(IF(COUNTIF(S34:T34,"N/A")>=1,"N/A","-"))))))) | S34: P | T34: P | U34: =IF(COUNTIF(V34:W34,"F")>=1,"FAIL",(IF(COUNTIF(V34:W34,"P")>=1,"PASS",(IF(COUNTIF(V34:W34,"N/T")>=1,"N/T",(IF(COUNTIF(V34:W34,"N/A")>=1,"N/A","-"))))))) | V34: P | W34: P | X34: SPAQA-15625 SPAQA-25093 SPAQA-24505 SPAQA-24846 SPAQA-24844 SPAQA-26515
A35: Q_012 | B35: TC_MAP_0007 | C35: Map | D35: Common | E35: 지도 재진입 | F35: 지도 재진입 | G35: KR, EU, NA | I35: 5 | J35: 1. 내 차 위치 조회 불가, 내 위치 조회 가능할 경우 | L35: 1. Map 진입 2. 메인 지도 확인 | M35: 1. 내 위치 마커 포커스 2. Default 줌레벨로 원복 | N35: =IF(COUNTIF(P35:W35,"F")>=1,"FAIL",(IF(COUNTIF(P35:W35,"P")>=1,"PASS",(IF(COUNTIF(P35:W35,"N/T")>=1,"N/T",(IF(COUNTIF(P35:W35,"N/A")>=1,"N/A","-"))))))) | O35: =IF(COUNTIF(P35:Q35,"F")>=1,"FAIL",(IF(COUNTIF(P35:Q35,"P")>=1,"PASS",(IF(COUNTIF(P35:Q35,"N/T")>=1,"N/T",(IF(COUNTIF(P35:Q35,"N/A")>=1,"N/A","-"))))))) | P35: P | Q35: P | R35: =IF(COUNTIF(S35:T35,"F")>=1,"FAIL",(IF(COUNTIF(S35:T35,"P")>=1,"PASS",(IF(COUNTIF(S35:T35,"N/T")>=1,"N/T",(IF(COUNTIF(S35:T35,"N/A")>=1,"N/A","-"))))))) | S35: P | T35: P | U35: =IF(COUNTIF(V35:W35,"F")>=1,"FAIL",(IF(COUNTIF(V35:W35,"P")>=1,"PASS",(IF(COUNTIF(V35:W35,"N/T")>=1,"N/T",(IF(COUNTIF(V35:W35,"N/A")>=1,"N/A","-"))))))) | V35: P | W35: P | X35: SPAQA-24199 SPAQA-24207 SPAQA-25682
B36: TC_MAP_0008 | C36: Map | D36: Common | E36: 지도 재진입 | F36: 지도 재진입 | G36: KR, EU, NA | I36: 5 | J36: 1. 내 차 위치, 내 위치 조회 불가할 경우 | L36: 1. Map 진입 2. 메인 지도 확인 | M36: 1. Default 위치 포커스 2. Default 축척으로 원복 | N36: =IF(COUNTIF(P36:W36,"F")>=1,"FAIL",(IF(COUNTIF(P36:W36,"P")>=1,"PASS",(IF(COUNTIF(P36:W36,"N/T")>=1,"N/T",(IF(COUNTIF(P36:W36,"N/A")>=1,"N/A","-"))))))) | O36: =IF(COUNTIF(P36:Q36,"F")>=1,"FAIL",(IF(COUNTIF(P36:Q36,"P")>=1,"PASS",(IF(COUNTIF(P36:Q36,"N/T")>=1,"N/T",(IF(COUNTIF(P36:Q36,"N/A")>=1,"N/A","-"))))))) | P36: P | Q36: P | R36: =IF(COUNTIF(S36:T36,"F")>=1,"FAIL",(IF(COUNTIF(S36:T36,"P")>=1,"PASS",(IF(COUNTIF(S36:T36,"N/T")>=1,"N/T",(IF(COUNTIF(S36:T36,"N/A")>=1,"N/A","-"))))))) | S36: P | T36: P | U36: =IF(COUNTIF(V36:W36,"F")>=1,"FAIL",(IF(COUNTIF(V36:W36,"P")>=1,"PASS",(IF(COUNTIF(V36:W36,"N/T")>=1,"N/T",(IF(COUNTIF(V36:W36,"N/A")>=1,"N/A","-"))))))) | V36: P | W36: P | Z36: 내 위치 OFF: App 내 위치 권한 OFF 내 차 위치 OFF: E-privacy 미지원 차량에서 Servicelist OFF
B37: TC_MAP_0009 | C37: Map | D37: Common | E37: 지도 재진입 | F37: 지도 재진입 | G37: KR, EU, NA | I37: 4 | L37: 1. Map 진입 2. BG 갔다가 FG 화면 복귀 3. 메인 지도 확인 | M37: 1. 지도 위치 / 줌레벨 유지 (이전 상태 유지) | N37: =IF(COUNTIF(P37:W37,"F")>=1,"FAIL",(IF(COUNTIF(P37:W37,"P")>=1,"PASS",(IF(COUNTIF(P37:W37,"N/T")>=1,"N/T",(IF(COUNTIF(P37:W37,"N/A")>=1,"N/A","-"))))))) | O37: =IF(COUNTIF(P37:Q37,"F")>=1,"FAIL",(IF(COUNTIF(P37:Q37,"P")>=1,"PASS",(IF(COUNTIF(P37:Q37,"N/T")>=1,"N/T",(IF(COUNTIF(P37:Q37,"N/A")>=1,"N/A","-"))))))) | P37: P | Q37: P | R37: =IF(COUNTIF(S37:T37,"F")>=1,"FAIL",(IF(COUNTIF(S37:T37,"P")>=1,"PASS",(IF(COUNTIF(S37:T37,"N/T")>=1,"N/T",(IF(COUNTIF(S37:T37,"N/A")>=1,"N/A","-"))))))) | S37: P | T37: P | U37: =IF(COUNTIF(V37:W37,"F")>=1,"FAIL",(IF(COUNTIF(V37:W37,"P")>=1,"PASS",(IF(COUNTIF(V37:W37,"N/T")>=1,"N/T",(IF(COUNTIF(V37:W37,"N/A")>=1,"N/A","-"))))))) | V37: P | W37: P | X37: SPAQA-26153
B38: TC_MAP_0010 | C38: Map | D38: Common | E38: 지도 재진입 | F38: 지도 재진입 | G38: KR, EU, NA | I38: 5 | K38: 1. 실차 주행 가능 상태 | L38: 1. Map 진입 2. BG 화면으로 전환 3. 실차 주행하여 다른 위치로 이동 4. FG 화면 복귀 5. 메인 지도 내 내 차 위치 마커 확인 | M38: 1. 이동한 위치에 맞게 내 차 위치 마커 업데이트 됨 | N38: =IF(COUNTIF(P38:W38,"F")>=1,"FAIL",(IF(COUNTIF(P38:W38,"P")>=1,"PASS",(IF(COUNTIF(P38:W38,"N/T")>=1,"N/T",(IF(COUNTIF(P38:W38,"N/A")>=1,"N/A","-"))))))) | O38: =IF(COUNTIF(P38:Q38,"F")>=1,"FAIL",(IF(COUNTIF(P38:Q38,"P")>=1,"PASS",(IF(COUNTIF(P38:Q38,"N/T")>=1,"N/T",(IF(COUNTIF(P38:Q38,"N/A")>=1,"N/A","-"))))))) | P38: N/T | Q38: N/T | R38: =IF(COUNTIF(S38:T38,"F")>=1,"FAIL",(IF(COUNTIF(S38:T38,"P")>=1,"PASS",(IF(COUNTIF(S38:T38,"N/T")>=1,"N/T",(IF(COUNTIF(S38:T38,"N/A")>=1,"N/A","-"))))))) | S38: N/T | T38: N/T | U38: =IF(COUNTIF(V38:W38,"F")>=1,"FAIL",(IF(COUNTIF(V38:W38,"P")>=1,"PASS",(IF(COUNTIF(V38:W38,"N/T")>=1,"N/T",(IF(COUNTIF(V38:W38,"N/A")>=1,"N/A","-"))))))) | V38: N/T | W38: N/T | Z38: (공통) 차량 위치가 유럽으로 고정되어 있어 확인 불가(N/T) | AA38: N/T : 외부 환경 필요(환경) | AB38: 실차
B39: TC_MAP_0011 | C39: Map | D39: Common | E39: 지도 재진입 | F39: 지도 재진입 | G39: KR, EU, NA | I39: 5 | K39: 1. 실차 주행 가능 상태 | L39: 1. Map 진입 2. BG 화면으로 전환 3. 실차 주행하여 다른 위치로 이동 4. FG 화면 복귀 5. 홈 탭 내 내 차 위치 영역 확인 | M39: 1. 이동한 위치에 맞는 주소 및 직선 거리 업데이트 됨 | N39: =IF(COUNTIF(P39:W39,"F")>=1,"FAIL",(IF(COUNTIF(P39:W39,"P")>=1,"PASS",(IF(COUNTIF(P39:W39,"N/T")>=1,"N/T",(IF(COUNTIF(P39:W39,"N/A")>=1,"N/A","-"))))))) | O39: =IF(COUNTIF(P39:Q39,"F")>=1,"FAIL",(IF(COUNTIF(P39:Q39,"P")>=1,"PASS",(IF(COUNTIF(P39:Q39,"N/T")>=1,"N/T",(IF(COUNTIF(P39:Q39,"N/A")>=1,"N/A","-"))))))) | P39: N/T | Q39: N/T | R39: =IF(COUNTIF(S39:T39,"F")>=1,"FAIL",(IF(COUNTIF(S39:T39,"P")>=1,"PASS",(IF(COUNTIF(S39:T39,"N/T")>=1,"N/T",(IF(COUNTIF(S39:T39,"N/A")>=1,"N/A","-"))))))) | S39: N/T | T39: N/T | U39: =IF(COUNTIF(V39:W39,"F")>=1,"FAIL",(IF(COUNTIF(V39:W39,"P")>=1,"PASS",(IF(COUNTIF(V39:W39,"N/T")>=1,"N/T",(IF(COUNTIF(V39:W39,"N/A")>=1,"N/A","-"))))))) | V39: N/T | W39: N/T | Z39: (공통) 차량 위치가 유럽으로 고정되어 있어 확인 불가(N/T) | AA39: N/T : 외부 환경 필요(환경) | AB39: 실차
B40: TC_MAP_0012 | C40: Map | D40: Common | E40: 지도 재진입 | F40: 지도 재진입 | G40: KR, EU, NA | I40: 4 | L40: 1. Map 진입 2. 다른 화면 이동 3. [<] 또는 [X] 버튼 사용하여 기존 화면 복귀 | M40: 1. 지도 위치 / 줌레벨 유지 (이전 상태 유지) | N40: =IF(COUNTIF(P40:W40,"F")>=1,"FAIL",(IF(COUNTIF(P40:W40,"P")>=1,"PASS",(IF(COUNTIF(P40:W40,"N/T")>=1,"N/T",(IF(COUNTIF(P40:W40,"N/A")>=1,"N/A","-"))))))) | O40: =IF(COUNTIF(P40:Q40,"F")>=1,"FAIL",(IF(COUNTIF(P40:Q40,"P")>=1,"PASS",(IF(COUNTIF(P40:Q40,"N/T")>=1,"N/T",(IF(COUNTIF(P40:Q40,"N/A")>=1,"N/A","-"))))))) | P40: P | Q40: P | R40: =IF(COUNTIF(S40:T40,"F")>=1,"FAIL",(IF(COUNTIF(S40:T40,"P")>=1,"PASS",(IF(COUNTIF(S40:T40,"N/T")>=1,"N/T",(IF(COUNTIF(S40:T40,"N/A")>=1,"N/A","-"))))))) | S40: P | T40: P | U40: =IF(COUNTIF(V40:W40,"F")>=1,"FAIL",(IF(COUNTIF(V40:W40,"P")>=1,"PASS",(IF(COUNTIF(V40:W40,"N/T")>=1,"N/T",(IF(COUNTIF(V40:W40,"N/A")>=1,"N/A","-"))))))) | V40: P | W40: P
B41: TC_MAP_0013 | C41: Map | D41: Common | E41: 지도 재진입 | F41: 지도 재진입 | G41: KR, EU, NA | I41: 4 | J41: 1. 내 차 위치 버튼 On 상태 | L41: 1. Map 진입 2. 다른 화면 이동 3. [<] 또는 [X] 버튼 사용하여 기존 화면 복귀 | M41: 1. 내 차 위치 버튼 비활성화 * [내 차 위치]는 FSM이므로 해당되지 않음 | N41: =IF(COUNTIF(P41:W41,"F")>=1,"FAIL",(IF(COUNTIF(P41:W41,"P")>=1,"PASS",(IF(COUNTIF(P41:W41,"N/T")>=1,"N/T",(IF(COUNTIF(P41:W41,"N/A")>=1,"N/A","-"))))))) | O41: =IF(COUNTIF(P41:Q41,"F")>=1,"FAIL",(IF(COUNTIF(P41:Q41,"P")>=1,"PASS",(IF(COUNTIF(P41:Q41,"N/T")>=1,"N/T",(IF(COUNTIF(P41:Q41,"N/A")>=1,"N/A","-"))))))) | P41: P | Q41: P | R41: =IF(COUNTIF(S41:T41,"F")>=1,"FAIL",(IF(COUNTIF(S41:T41,"P")>=1,"PASS",(IF(COUNTIF(S41:T41,"N/T")>=1,"N/T",(IF(COUNTIF(S41:T41,"N/A")>=1,"N/A","-"))))))) | S41: P | T41: P | U41: =IF(COUNTIF(V41:W41,"F")>=1,"FAIL",(IF(COUNTIF(V41:W41,"P")>=1,"PASS",(IF(COUNTIF(V41:W41,"N/T")>=1,"N/T",(IF(COUNTIF(V41:W41,"N/A")>=1,"N/A","-"))))))) | V41: P | W41: P | X41: SPAQA-23887
B42: TC_MAP_0014 | C42: Map | D42: Common | E42: 지도 재진입 | F42: 지도 재진입 | G42: KR, EU, NA | I42: 4 | J42: 1. 내 위치 버튼 On 상태 | L42: 1. Map 진입 2. 다른 화면 이동 3. [<] 또는 [X] 버튼 사용하여 기존 화면 복귀 | M42: 1. 내 위치 버튼 비활성화 | N42: =IF(COUNTIF(P42:W42,"F")>=1,"FAIL",(IF(COUNTIF(P42:W42,"P")>=1,"PASS",(IF(COUNTIF(P42:W42,"N/T")>=1,"N/T",(IF(COUNTIF(P42:W42,"N/A")>=1,"N/A","-"))))))) | O42: =IF(COUNTIF(P42:Q42,"F")>=1,"FAIL",(IF(COUNTIF(P42:Q42,"P")>=1,"PASS",(IF(COUNTIF(P42:Q42,"N/T")>=1,"N/T",(IF(COUNTIF(P42:Q42,"N/A")>=1,"N/A","-"))))))) | P42: P | Q42: P | R42: =IF(COUNTIF(S42:T42,"F")>=1,"FAIL",(IF(COUNTIF(S42:T42,"P")>=1,"PASS",(IF(COUNTIF(S42:T42,"N/T")>=1,"N/T",(IF(COUNTIF(S42:T42,"N/A")>=1,"N/A","-"))))))) | S42: P | T42: P | U42: =IF(COUNTIF(V42:W42,"F")>=1,"FAIL",(IF(COUNTIF(V42:W42,"P")>=1,"PASS",(IF(COUNTIF(V42:W42,"N/T")>=1,"N/T",(IF(COUNTIF(V42:W42,"N/A")>=1,"N/A","-"))))))) | V42: P | W42: P
...

Sheet My Car
A1: ㄴ | C1: TC 추가 NO : | D1: =IFERROR(__xludf.DUMMYFUNCTION("""TC_""&""MyCar""&""_""&TEXT(ARRAYFORMULA(MAX(IFERROR(VALUE(REGEXEXTRACT(B28:B1694, ""\d+"")))))+1,""0000"")"),"TC_MyCar_0560")
B2: CCI One App | E2: EU FullTC | L2: =Control!L2 | M2: =IF(COUNTIF(N2:O2,"F")>=1,"FAIL",(IF(COUNTIF(N2:O2,"P")>=1,"PASS",(IF(COUNTIF(N2:O2,"N/T")>=1,"N/T",(IF(COUNTIF(N2:O2,"N/A")>=1,"N/A","-"))))))) | O2: 추가 | P2: 수정 | Q2: 삭제
E3: Project | H3: UID ver. | L3: =Control!L3 | M3: =IF(COUNTIF(N3:O3,"F")>=1,"FAIL",(IF(COUNTIF(N3:O3,"P")>=1,"PASS",(IF(COUNTIF(N3:O3,"N/T")>=1,"N/T",(IF(COUNTIF(N3:O3,"N/A")>=1,"N/A","-"))))))) | O3: =COUNTIFS($AB:$AB,"*"&O2&"*") | P3: =COUNTIFS($AB:$AB,"*"&P2&"*") | Q3: =COUNTIFS($AB:$AB,"*"&Q2&"*")
E4: 담당자 | H4: 작성일자 | L4: =Control!L4 | M4: =IF(COUNTIF(N4:O4,"F")>=1,"FAIL",(IF(COUNTIF(N4:O4,"P")>=1,"PASS",(IF(COUNTIF(N4:O4,"N/T")>=1,"N/T",(IF(COUNTIF(N4:O4,"N/A")>=1,"N/A","-")))))))
L5: =Control!L5 | M5: =IF(COUNTIF(N5:O5,"F")>=1,"FAIL",(IF(COUNTIF(N5:O5,"P")>=1,"PASS",(IF(COUNTIF(N5:O5,"N/T")>=1,"N/T",(IF(COUNTIF(N5:O5,"N/A")>=1,"N/A","-"))))))) | N5: ← 색깔 업뎃 시 직접 색 지정하지 말고, 이거 복붙해 주세요(누가 처리 했는지 히스토리 보관용)
B6: 테스트 환경
B7: Tester
B9: Test Target | D9: Total TC | E9: RunRate | F9: PassRate | G9: PASS | H9: FAIL | I9: N/A | J9: N/T | N9: Brand | O9: KOA | R9: HOA | U9: GOA
B10: Total | D10: =SUM(D11:D18) | E10: =IFERROR(SUM($G10:J10)/$D10,"-") | F10: =IFERROR($G10/(SUM(G10:H10)),"-") | G10: =SUM(G11:G18) | H10: =SUM(H11:H18) | I10: =SUM(I11:I18) | J10: =SUM(J11:J18) | N10: OS 별 결과 | O10: Total | P10: Android | Q10: iOS | R10: Total | S10: Android | T10: iOS | U10: Total
B11: My Car | C11: Common | D11: =COUNTIF($D$22:$D$8766,$C11) | E11: =IFERROR(SUM($G11:J11)/$D11,"-") | F11: =IFERROR($G11/(SUM(G11:H11)),"-") | G11: =COUNTIFS($D:$D,$C11,$N:$N,G$9) | H11: =COUNTIFS($D:$D,$C11,$N:$N,H$9) | I11: =COUNTIFS($D:$D,$C11,$N:$N,I$9) | J11: =COUNTIFS($D:$D,$C11,$N:$N,J$9) | N11: Total | O11: =SUM(O12:O15) | P11: =SUM(P12:P15) | Q11: =SUM(Q12:Q15) | R11: =SUM(R12:R15) | S11: =SUM(S12:S15) | T11: =SUM(T12:T15) | U11: =SUM(U12:U15)
C12: CCS 가입 정보 | D12: =COUNTIF($D$22:$D$8766,$C12) | E12: =IFERROR(SUM($G12:J12)/$D12,"-") | F12: =IFERROR($G12/(SUM(G12:H12)),"-") | G12: =COUNTIFS($D:$D,$C12,$N:$N,G$9) | H12: =COUNTIFS($D:$D,$C12,$N:$N,H$9) | I12: =COUNTIFS($D:$D,$C12,$N:$N,I$9) | J12: =COUNTIFS($D:$D,$C12,$N:$N,J$9) | N12: PASS | O12: =COUNTIFS(O$22:O$10136,$N12) | P12: =COUNTIFS(P$22:P$10136,"P") | Q12: =COUNTIFS(Q$22:Q$10136,"P") | R12: =COUNTIFS(R$22:R$10136,$N12) | S12: =COUNTIFS(S$22:S$10136,"P") | T12: =COUNTIFS(T$22:T$10136,"P") | U12: =COUNTIFS(U$22:U$10136,$N12)
C13: 차량 공유 및 프로필 | D13: =COUNTIF($D$22:$D$8766,$C13) | E13: =IFERROR(SUM($G13:J13)/$D13,"-") | F13: =IFERROR($G13/(SUM(G13:H13)),"-") | G13: =COUNTIFS($D:$D,$C13,$N:$N,G$9) | H13: =COUNTIFS($D:$D,$C13,$N:$N,H$9) | I13: =COUNTIFS($D:$D,$C13,$N:$N,I$9) | J13: =COUNTIFS($D:$D,$C13,$N:$N,J$9) | N13: FAIL | O13: =COUNTIFS(O$22:O$10136,$N13) | P13: =COUNTIFS(P$22:P$10136,"F") | Q13: =COUNTIFS(Q$22:Q$10136,"F") | R13: =COUNTIFS(R$22:R$10136,$N13) | S13: =COUNTIFS(S$22:S$10136,"F") | T13: =COUNTIFS(T$22:T$10136,"F") | U13: =COUNTIFS(U$22:U$10136,$N13)
C14: 디지털 키 | D14: =COUNTIF($D$22:$D$8766,$C14) | E14: =IFERROR(SUM($G14:J14)/$D14,"-") | F14: =IFERROR($G14/(SUM(G14:H14)),"-") | G14: =COUNTIFS($D:$D,$C14,$N:$N,G$9) | H14: =COUNTIFS($D:$D,$C14,$N:$N,H$9) | I14: =COUNTIFS($D:$D,$C14,$N:$N,I$9) | J14: =COUNTIFS($D:$D,$C14,$N:$N,J$9) | N14: N/A | O14: =COUNTIFS(O$22:O$10136,$N14) | P14: =COUNTIFS(P$22:P$10136,$N14) | Q14: =COUNTIFS(Q$22:Q$10136,$N14) | R14: =COUNTIFS(R$22:R$10136,$N14) | S14: =COUNTIFS(S$22:S$10136,$N14) | T14: =COUNTIFS(T$22:T$10136,$N14) | U14: =COUNTIFS(U$22:U$10136,$N14)
C15: 연동 서비스 | D15: =COUNTIF($D$22:$D$8766,$C15) | E15: =IFERROR(SUM($G15:J15)/$D15,"-") | F15: =IFERROR($G15/(SUM(G15:H15)),"-") | G15: =COUNTIFS($D:$D,$C15,$N:$N,G$9) | H15: =COUNTIFS($D:$D,$C15,$N:$N,H$9) | I15: =COUNTIFS($D:$D,$C15,$N:$N,I$9) | J15: =COUNTIFS($D:$D,$C15,$N:$N,J$9) | N15: N/T | O15: =COUNTIFS(O$22:O$10136,$N15) | P15: =COUNTIFS(P$22:P$10136,$N15) | Q15: =COUNTIFS(Q$22:Q$10136,$N15) | R15: =COUNTIFS(R$22:R$10136,$N15) | S15: =COUNTIFS(S$22:S$10136,$N15) | T15: =COUNTIFS(T$22:T$10136,$N15) | U15: =COUNTIFS(U$22:U$10136,$N15)
C16: 그 외 | D16: =COUNTIF($D$20:$D$8764,$C16) | E16: =IFERROR(SUM($G16:J16)/$D16,"-") | F16: =IFERROR($G16/(SUM(G16:H16)),"-") | G16: =COUNTIFS($D:$D,$C16,$N:$N,G$9) | H16: =COUNTIFS($D:$D,$C16,$N:$N,H$9) | I16: =COUNTIFS($D:$D,$C16,$N:$N,I$9) | J16: =COUNTIFS($D:$D,$C16,$N:$N,J$9)
C17: 라이팅 패턴 설정 | D17: =COUNTIF($D$20:$D$8764,$C17) | E17: =IFERROR(SUM($G17:J17)/$D17,"-") | F17: =IFERROR($G17/(SUM(G17:H17)),"-") | G17: =COUNTIFS($D:$D,$C17,$N:$N,G$9) | H17: =COUNTIFS($D:$D,$C17,$N:$N,H$9) | I17: =COUNTIFS($D:$D,$C17,$N:$N,I$9) | J17: =COUNTIFS($D:$D,$C17,$N:$N,J$9)
C18: 차량 소프트웨어 버전 | D18: =COUNTIF($D$20:$D$8764,$C18) | E18: =IFERROR(SUM($G18:J18)/$D18,"-") | F18: =IFERROR($G18/(SUM(G18:H18)),"-") | G18: =COUNTIFS($D:$D,$C18,$N:$N,G$9) | H18: =COUNTIFS($D:$D,$C18,$N:$N,H$9) | I18: =COUNTIFS($D:$D,$C18,$N:$N,I$9) | J18: =COUNTIFS($D:$D,$C18,$N:$N,J$9)
B20: TC ID | C20: 카테고리 | D20: 대분류 | E20: 중분류 | F20: 소분류 | G20: 향지 | H20: 브랜드 | I20: 우선순위 | J20: Pre-condition | L20: TC procedure | M20: Expected result | N20: Result | O20: KOA Result | P20: KOA | R20: HOA Result | S20: HOA | U20: GOA Result | V20: GOA | X20: Closed 지라 NO | Y20: 지라 NO. | Z20: NT/NA 상세 사유 | AA20: N/A N/T 필터 | AB20: LABEL
J21: App 동작 조건 | K21: 차량 동작 조건 | M21: 1. 팝업 표출 Please grant user profile permissions to use the service Please ask the vehicle's main user for permission to add a new profile. [Close] (*Close 선택 시 팝업 닫힘) | P21: Android | Q21: iOS | S21: Android | T21: iOS | V21: Android | W21: iOS
B22: TC_MyCar_0001 | C22: My Car | D22: Common | E22: Common | F22: 개인화 4단계 프로필 연동 상태 안내 | G22: EU | I22: 4 | J22: 1. 프로필 미등록 2. 주사용자 | K22: 1. 프로필 미등록 2. 주사용자 | L22: 1. My Car 진입 2. 차량 관리 메뉴 진입 3. 연동 서비스 메뉴 진입 - 캘린더 서비스 - 스트리밍 서비스 | M22: 1. 팝업 표출 Please grant user profile permissions to use the service. Please register your profile in the profile settings. [Register profile] [Close] (*Close 선택 시 팝업 닫힘) | N22: =IF(COUNTIF(P22:W22,"F")>=1,"FAIL",(IF(COUNTIF(P22:W22,"P")>=1,"PASS",(IF(COUNTIF(P22:W22,"N/T")>=1,"N/T",(IF(COUNTIF(P22:W22,"N/A")>=1,"N/A","-"))))))) | O22: =IF(COUNTIF(P22:Q22,"F")>=1,"FAIL",(IF(COUNTIF(P22:Q22,"P")>=1,"PASS",(IF(COUNTIF(P22:Q22,"N/T")>=1,"N/T",(IF(COUNTIF(P22:Q22,"N/A")>=1,"N/A","-"))))))) | P22: N/T | Q22: N/T | R22: =IF(COUNTIF(S22:T22,"F")>=1,"FAIL",(IF(COUNTIF(S22:T22,"P")>=1,"PASS",(IF(COUNTIF(S22:T22,"N/T")>=1,"N/T",(IF(COUNTIF(S22:T22,"N/A")>=1,"N/A","-"))))))) | S22: P | T22: P | U22: =IF(COUNTIF(V22:W22,"F")>=1,"FAIL",(IF(COUNTIF(V22:W22,"P")>=1,"PASS",(IF(COUNTIF(V22:W22,"N/T")>=1,"N/T",(IF(COUNTIF(V22:W22,"N/A")>=1,"N/A","-"))))))) | V22: P | W22: P | Z22: K : MV원격사용불가(방전) (N/T) | AB22: 개인화, 실차
B23: TC_MyCar_0002 | C23: My Car | D23: Common | E23: Common | F23: 개인화 4단계 프로필 연동 상태 안내 | G23: EU | I23: 4 | J23: 1. 프로필 미등록 2. 주사용자 | K23: 1. 개인화 4단계 차량 또는 지역 | L23: 1. My Car 진입 2. 차량 관리 메뉴 진입 3. 연동 서비스 메뉴 진입 - 캘린더 서비스 - 스트리밍 서비스 4. [Register profile] 버튼 선택 | M23: 1. Manage Profile 이동 | N23: =IF(COUNTIF(P23:W23,"F")>=1,"FAIL",(IF(COUNTIF(P23:W23,"P")>=1,"PASS",(IF(COUNTIF(P23:W23,"N/T")>=1,"N/T",(IF(COUNTIF(P23:W23,"N/A")>=1,"N/A","-"))))))) | O23: =IF(COUNTIF(P23:Q23,"F")>=1,"FAIL",(IF(COUNTIF(P23:Q23,"P")>=1,"PASS",(IF(COUNTIF(P23:Q23,"N/T")>=1,"N/T",(IF(COUNTIF(P23:Q23,"N/A")>=1,"N/A","-"))))))) | P23: N/T | Q23: N/T | R23: =IF(COUNTIF(S23:T23,"F")>=1,"FAIL",(IF(COUNTIF(S23:T23,"P")>=1,"PASS",(IF(COUNTIF(S23:T23,"N/T")>=1,"N/T",(IF(COUNTIF(S23:T23,"N/A")>=1,"N/A","-"))))))) | S23: P | T23: P | U23: =IF(COUNTIF(V23:W23,"F")>=1,"FAIL",(IF(COUNTIF(V23:W23,"P")>=1,"PASS",(IF(COUNTIF(V23:W23,"N/T")>=1,"N/T",(IF(COUNTIF(V23:W23,"N/A")>=1,"N/A","-"))))))) | V23: P | W23: P | Z23: K : MV원격사용불가(방전) (N/T) | AB23: 개인화, 실차
B24: TC_MyCar_0003 | C24: My Car | D24: Common | E24: Common | F24: 개인화 4단계 프로필 연동 상태 안내 | G24: EU | I24: 4 | J24: 1. 프로필 미등록 2. 피공유자 | K24: 1. 개인화 4단계 차량 또는 지역 | L24: 1. My Car 진입 2. 차량 관리 메뉴 진입 3. 연동 서비스 메뉴 진입 - 캘린더 서비스 - 스트리밍 서비스 | M24: 1. 팝업 표출 Please grant user profile permissions to use the service Please ask the vehicle's main user for permission to add a new profile. [Close] (*Close 선택 시 팝업 닫힘) | N24: =IF(COUNTIF(P24:W24,"F")>=1,"FAIL",(IF(COUNTIF(P24:W24,"P")>=1,"PASS",(IF(COUNTIF(P24:W24,"N/T")>=1,"N/T",(IF(COUNTIF(P24:W24,"N/A")>=1,"N/A","-"))))))) | O24: =IF(COUNTIF(P24:Q24,"F")>=1,"FAIL",(IF(COUNTIF(P24:Q24,"P")>=1,"PASS",(IF(COUNTIF(P24:Q24,"N/T")>=1,"N/T",(IF(COUNTIF(P24:Q24,"N/A")>=1,"N/A","-"))))))) | P24: P | Q24: P | R24: =IF(COUNTIF(S24:T24,"F")>=1,"FAIL",(IF(COUNTIF(S24:T24,"P")>=1,"PASS",(IF(COUNTIF(S24:T24,"N/T")>=1,"N/T",(IF(COUNTIF(S24:T24,"N/A")>=1,"N/A","-"))))))) | S24: P | T24: P | U24: =IF(COUNTIF(V24:W24,"F")>=1,"FAIL",(IF(COUNTIF(V24:W24,"P")>=1,"PASS",(IF(COUNTIF(V24:W24,"N/T")>=1,"N/T",(IF(COUNTIF(V24:W24,"N/A")>=1,"N/A","-"))))))) | V24: P | W24: P | X24: SPAQA-12319 | Z24: K : wbkong@poliot.co.kr 계정으로 확인 | AB24: 개인화, 실차
B25: TC_MyCar_0004 | C25: My Car | D25: Common | E25: Common | F25: 개인화 4단계 프로필 연동 상태 안내 | G25: EU | I25: 4 | J25: 1. 프로필 미연동 | K25: 1. 개인화 4단계 차량 또는 지역 | L25: 1. My Car 진입 2. 차량 관리 메뉴 진입 3. 연동 서비스 메뉴 진입 - 캘린더 서비스 - 스트리밍 서비스 | M25: 1. 팝업 표출 Profile sync has not been completed. Please complete setting up your user profile in the vehicle. ※ If the Problem persists, please contact the Customer Centre. [Customer centre] [Close] (*Close 선택 시 팝업 닫힘) | N25: =IF(COUNTIF(P25:W25,"F")>=1,"FAIL",(IF(COUNTIF(P25:W25,"P")>=1,"PASS",(IF(COUNTIF(P25:W25,"N/T")>=1,"N/T",(IF(COUNTIF(P25:W25,"N/A")>=1,"N/A","-"))))))) | O25: =IF(COUNTIF(P25:Q25,"F")>=1,"FAIL",(IF(COUNTIF(P25:Q25,"P")>=1,"PASS",(IF(COUNTIF(P25:Q25,"N/T")>=1,"N/T",(IF(COUNTIF(P25:Q25,"N/A")>=1,"N/A","-"))))))) | P25: P | Q25: P | R25: =IF(COUNTIF(S25:T25,"F")>=1,"FAIL",(IF(COUNTIF(S25:T25,"P")>=1,"PASS",(IF(COUNTIF(S25:T25,"N/T")>=1,"N/T",(IF(COUNTIF(S25:T25,"N/A")>=1,"N/A","-"))))))) | S25: P | T25: P | U25: =IF(COUNTIF(V25:W25,"F")>=1,"FAIL",(IF(COUNTIF(V25:W25,"P")>=1,"PASS",(IF(COUNTIF(V25:W25,"N/T")>=1,"N/T",(IF(COUNTIF(V25:W25,"N/A")>=1,"N/A","-"))))))) | V25: P | W25: P | X25: SPAQA-14472 SPAQA-14482 SPAQA-15337 SPAQA-19199 SPAQA-15136 | AB25: 개인화, 실차
B26: TC_MyCar_0005 | C26: My Car | D26: Common | E26: Common | F26: 개인화 4단계 프로필 연동 상태 안내 | G26: EU | I26: 4 | J26: 1. 프로필 미연동 | K26: 1. 개인화 4단계 차량 또는 지역 | L26: 1. My Car 진입 2. 차량 관리 메뉴 진입 3. 연동 서비스 메뉴 진입 - 캘린더 서비스 - 스트리밍 서비스 4. [Customer centre] 버튼 선택 | M26: 1. 고객센터 홈페이지 이동 | N26: =IF(COUNTIF(P26:W26,"F")>=1,"FAIL",(IF(COUNTIF(P26:W26,"P")>=1,"PASS",(IF(COUNTIF(P26:W26,"N/T")>=1,"N/T",(IF(COUNTIF(P26:W26,"N/A")>=1,"N/A","-"))))))) | O26: =IF(COUNTIF(P26:Q26,"F")>=1,"FAIL",(IF(COUNTIF(P26:Q26,"P")>=1,"PASS",(IF(COUNTIF(P26:Q26,"N/T")>=1,"N/T",(IF(COUNTIF(P26:Q26,"N/A")>=1,"N/A","-"))))))) | P26: P | Q26: P | R26: =IF(COUNTIF(S26:T26,"F")>=1,"FAIL",(IF(COUNTIF(S26:T26,"P")>=1,"PASS",(IF(COUNTIF(S26:T26,"N/T")>=1,"N/T",(IF(COUNTIF(S26:T26,"N/A")>=1,"N/A","-"))))))) | S26: P | T26: P | U26: =IF(COUNTIF(V26:W26,"F")>=1,"FAIL",(IF(COUNTIF(V26:W26,"P")>=1,"PASS",(IF(COUNTIF(V26:W26,"N/T")>=1,"N/T",(IF(COUNTIF(V26:W26,"N/A")>=1,"N/A","-"))))))) | V26: P | W26: P | X26: SPAQA-12012 SPAQA-12319 SPAQA-13136 SPAQA-13101 SPAQA-13440 SPAQA-20927 SPAQA-14502 | AB26: 개인화, 실차
B27: TC_MyCar_0007 | C27: My Car | D27: Common | E27: Common | F27: 서비스 리스트 OFF시 표시 정책 | G27: EU | J27: 1. Service List Off | K27: 1. ePrivacy 지원 차량 | L27: 1. MyCar 진입 2. Digital Key Management, External Services, Alert Services, User profile backup 진입 | M27: 1. 해당 탭 진입 시 Service List off 안내 배너 노출 된다. - The service is restricted or unavailable. Check [Privacy Settings] under {AVN_SERVICE_NAME}menu in the vehicle's navigation system. ※ Service List 화면 미제공 | N27: =IF(COUNTIF(P27:W27,"F")>=1,"FAIL",(IF(COUNTIF(P27:W27,"P")>=1,"PASS",(IF(COUNTIF(P27:W27,"N/T")>=1,"N/T",(IF(COUNTIF(P27:W27,"N/A")>=1,"N/A","-"))))))) | O27: =IF(COUNTIF(P27:Q27,"F")>=1,"FAIL",(IF(COUNTIF(P27:Q27,"P")>=1,"PASS",(IF(COUNTIF(P27:Q27,"N/T")>=1,"N/T",(IF(COUNTIF(P27:Q27,"N/A")>=1,"N/A","-"))))))) | P27: N/A | Q27: N/A | R27: =IF(COUNTIF(S27:T27,"F")>=1,"FAIL",(IF(COUNTIF(S27:T27,"P")>=1,"PASS",(IF(COUNTIF(S27:T27,"N/T")>=1,"N/T",(IF(COUNTIF(S27:T27,"N/A")>=1,"N/A","-"))))))) | S27: N/A | T27: N/A | U27: =IF(COUNTIF(V27:W27,"F")>=1,"FAIL",(IF(COUNTIF(V27:W27,"P")>=1,"PASS",(IF(COUNTIF(V27:W27,"N/T")>=1,"N/T",(IF(COUNTIF(V27:W27,"N/A")>=1,"N/A","-"))))))) | V27: N/A | W27: N/A | X27: SPAQA-17223 SPAQA-17224 SPAQA-17500 SPAQA-17298 SPAQA-17293 SPAQA-17203 | Z27: 중복 : TC_MyCar_0245 | AA27: 사양 아님(N/A) | AB27: 실차, 삭제
B28: TC_MyCar_0008 | C28: My Car | D28: Common | E28: Common | F28: 연동 서비스 진입 시 오류 팝업 | G28: KR, EU | I28: 5 | K28: 1. 대표 차량의 스트리밍 서비스 미지원 | L28: 1. MyCar 진입 2. 차량 관리 진입 3. 연동 서비스 진입 | M28: 1. 오류 팝업 표출 The main vehicle does not support this function. Please change the main vehicle and try again. [Close] * close 버튼 선택 시, 팝업 닫히고 현재 화면 유지 | N28: =IF(COUNTIF(P28:W28,"F")>=1,"FAIL",(IF(COUNTIF(P28:W28,"P")>=1,"PASS",(IF(COUNTIF(P28:W28,"N/T")>=1,"N/T",(IF(COUNTIF(P28:W28,"N/A")>=1,"N/A","-"))))))) | O28: =IF(COUNTIF(P28:Q28,"F")>=1,"FAIL",(IF(COUNTIF(P28:Q28,"P")>=1,"PASS",(IF(COUNTIF(P28:Q28,"N/T")>=1,"N/T",(IF(COUNTIF(P28:Q28,"N/A")>=1,"N/A","-"))))))) | P28: N/T | Q28: N/T | R28: =IF(COUNTIF(S28:T28,"F")>=1,"FAIL",(IF(COUNTIF(S28:T28,"P")>=1,"PASS",(IF(COUNTIF(S28:T28,"N/T")>=1,"N/T",(IF(COUNTIF(S28:T28,"N/A")>=1,"N/A","-"))))))) | S28: N/T | T28: N/T | U28: =IF(COUNTIF(V28:W28,"F")>=1,"FAIL",(IF(COUNTIF(V28:W28,"P")>=1,"PASS",(IF(COUNTIF(V28:W28,"N/T")>=1,"N/T",(IF(COUNTIF(V28:W28,"N/A")>=1,"N/A","-"))))))) | V28: N/T | W28: N/T | Z28: (공통) 스트리밍 서비스 미지원 차량 필요 | AA28: N/T : 차량/디바이스 필요(조건)
B29: TC_MyCar_0552 | C29: My Car | D29: CCS 가입 정보 | E29: CCS 가입 정보 | F29: CCS 가입 정보 | G29: KR, EU, NA, MX | H29: KOA, HOA | I29: 1 | J29: 1. 미로그인 | L29: 1. MyCar 진입 | M29: 1. 차량 관리 메뉴 미표출 2. 로그인 버튼 표출 | N29: =IF(COUNTIF(P29:W29,"F")>=1,"FAIL",(IF(COUNTIF(P29:W29,"P")>=1,"PASS",(IF(COUNTIF(P29:W29,"N/T")>=1,"N/T",(IF(COUNTIF(P29:W29,"N/A")>=1,"N/A","-"))))))) | O29: =IF(COUNTIF(P29:Q29,"F")>=1,"FAIL",(IF(COUNTIF(P29:Q29,"P")>=1,"PASS",(IF(COUNTIF(P29:Q29,"N/T")>=1,"N/T",(IF(COUNTIF(P29:Q29,"N/A")>=1,"N/A","-"))))))) | P29: P | Q29: P | R29: =IF(COUNTIF(S29:T29,"F")>=1,"FAIL",(IF(COUNTIF(S29:T29,"P")>=1,"PASS",(IF(COUNTIF(S29:T29,"N/T")>=1,"N/T",(IF(COUNTIF(S29:T29,"N/A")>=1,"N/A","-"))))))) | S29: P | T29: P | U29: =IF(COUNTIF(V29:W29,"F")>=1,"FAIL",(IF(COUNTIF(V29:W29,"P")>=1,"PASS",(IF(COUNTIF(V29:W29,"N/T")>=1,"N/T",(IF(COUNTIF(V29:W29,"N/A")>=1,"N/A","-"))))))) | V29: N/A | W29: N/A | Z29: G : 미로그인 시 마이카 진입 불가(N/A) | AA29: 사양 아님(N/A) | AB29: Sanity
B30: TC_MyCar_0553 | C30: My Car | D30: CCS 가입 정보 | E30: CCS 가입 정보 | F30: CCS 가입 정보 | G30: KR, EU, NA, MX | H30: KOA, HOA | I30: 1 | J30: 1. 미로그인 | L30: 1. MyCar 진입 2. 로그인 버튼 선택 | M30: 1. 로그인 화면 표출 | N30: =IF(COUNTIF(P30:W30,"F")>=1,"FAIL",(IF(COUNTIF(P30:W30,"P")>=1,"PASS",(IF(COUNTIF(P30:W30,"N/T")>=1,"N/T",(IF(COUNTIF(P30:W30,"N/A")>=1,"N/A","-"))))))) | O30: =IF(COUNTIF(P30:Q30,"F")>=1,"FAIL",(IF(COUNTIF(P30:Q30,"P")>=1,"PASS",(IF(COUNTIF(P30:Q30,"N/T")>=1,"N/T",(IF(COUNTIF(P30:Q30,"N/A")>=1,"N/A","-"))))))) | P30: P | Q30: P | R30: =IF(COUNTIF(S30:T30,"F")>=1,"FAIL",(IF(COUNTIF(S30:T30,"P")>=1,"PASS",(IF(COUNTIF(S30:T30,"N/T")>=1,"N/T",(IF(COUNTIF(S30:T30,"N/A")>=1,"N/A","-"))))))) | S30: P | T30: P | U30: =IF(COUNTIF(V30:W30,"F")>=1,"FAIL",(IF(COUNTIF(V30:W30,"P")>=1,"PASS",(IF(COUNTIF(V30:W30,"N/T")>=1,"N/T",(IF(COUNTIF(V30:W30,"N/A")>=1,"N/A","-"))))))) | V30: N/A | W30: N/A | Z30: G : 미로그인 시 마이카 진입 불가(N/A) | AA30: 사양 아님(N/A) | AB30: Sanity
B31: TC_MyCar_0009 | C31: My Car | D31: CCS 가입 정보 | E31: CCS 가입 정보 | F31: CCS 가입 정보 | G31: KR, EU | I31: 3 | J31: 1. CCS 미가입 상태 2. 차주인 경우 | L31: 1. My Car 진입 2. 차량 관리 진입 3. {CCS_SERVICE} 선택 | M31: 1. CCS 가입 화면 표출된다. | N31: =IF(COUNTIF(P31:W31,"F")>=1,"FAIL",(IF(COUNTIF(P31:W31,"P")>=1,"PASS",(IF(COUNTIF(P31:W31,"N/T")>=1,"N/T",(IF(COUNTIF(P31:W31,"N/A")>=1,"N/A","-"))))))) | O31: =IF(COUNTIF(P31:Q31,"F")>=1,"FAIL",(IF(COUNTIF(P31:Q31,"P")>=1,"PASS",(IF(COUNTIF(P31:Q31,"N/T")>=1,"N/T",(IF(COUNTIF(P31:Q31,"N/A")>=1,"N/A","-"))))))) | P31: P | Q31: P | R31: =IF(COUNTIF(S31:T31,"F")>=1,"FAIL",(IF(COUNTIF(S31:T31,"P")>=1,"PASS",(IF(COUNTIF(S31:T31,"N/T")>=1,"N/T",(IF(COUNTIF(S31:T31,"N/A")>=1,"N/A","-"))))))) | S31: P | T31: P | U31: =IF(COUNTIF(V31:W31,"F")>=1,"FAIL",(IF(COUNTIF(V31:W31,"P")>=1,"PASS",(IF(COUNTIF(V31:W31,"N/T")>=1,"N/T",(IF(COUNTIF(V31:W31,"N/A")>=1,"N/A","-"))))))) | V31: P | W31: P | X31: SPAQA-16856(TASK) SPAQA-19379 SPAQA-19136 SPAQA-25008 SPAQA-25722 | AB31: TASK, 실차
B32: TC_MyCar_0010 | C32: My Car | D32: CCS 가입 정보 | E32: CCS 가입 정보 | F32: CCS 가입 정보 | G32: KR, EU | I32: 1 | J32: 1. CCS 이용 불가 2. 차주인 경우 | K32: 1. 차량 Offline Mode OFF | L32: 1. My Car 진입 2. 차량 관리 진입 3. {CCS_SERVICE} 선택 | M32: 1. 가입일 , 만료일, 차대번호 표출 - Subscription date - Expiration date - Vin | N32: =IF(COUNTIF(P32:W32,"F")>=1,"FAIL",(IF(COUNTIF(P32:W32,"P")>=1,"PASS",(IF(COUNTIF(P32:W32,"N/T")>=1,"N/T",(IF(COUNTIF(P32:W32,"N/A")>=1,"N/A","-"))))))) | O32: =IF(COUNTIF(P32:Q32,"F")>=1,"FAIL",(IF(COUNTIF(P32:Q32,"P")>=1,"PASS",(IF(COUNTIF(P32:Q32,"N/T")>=1,"N/T",(IF(COUNTIF(P32:Q32,"N/A")>=1,"N/A","-"))))))) | P32: P | Q32: P | R32: =IF(COUNTIF(S32:T32,"F")>=1,"FAIL",(IF(COUNTIF(S32:T32,"P")>=1,"PASS",(IF(COUNTIF(S32:T32,"N/T")>=1,"N/T",(IF(COUNTIF(S32:T32,"N/A")>=1,"N/A","-"))))))) | S32: P | T32: P | U32: =IF(COUNTIF(V32:W32,"F")>=1,"FAIL",(IF(COUNTIF(V32:W32,"P")>=1,"PASS",(IF(COUNTIF(V32:W32,"N/T")>=1,"N/T",(IF(COUNTIF(V32:W32,"N/A")>=1,"N/A","-"))))))) | V32: P | W32: P | X32: SPAQA-16856(TASK) | AB32: CheckList, 실차, TASK
